Workbook

Sheet Начните здесь
D2: B2B SaaS
B3: Елизавета Трибунская | F3: tribunska.ru
B5: Три тарифа, три сценария и ваш способ продажи. Посчитайте, сколько компаний нужно привлечь и какие деньги потребуются на запуск.
B7: Изменить параметры | F7: Посмотреть результат
B9: На листе «Допущения» выберите сценарий и способ продажи, замените цены и расходы в жёлтых ячейках. Результат — на листе «Итог».
B11: Инструкция для ИИ-агента
B12: 1. Сначала расспроси владельца об идее, клиентах, географии, тарифах, способе продажи и расходах. Найди пробелы в данных. В книге три тарифа; сценарий экономики и способ продажи выбираются отдельно. 2. Проверь рекламу под эту аудиторию в Яндекс Директе, Google Ads, VK Рекламе и Facebook / Meta Ads там, где доступно размещение. Возьми из кабинетов прогноз цены клика, показов и кликов при выбранном бюджете. Поиск, рекламные сети, таргетинг и ретаргетинг оцени отдельно. Если доступа нет, попроси владельца прислать прогноз или выгрузку. 3. Приценивайся к тематическим блогерам и сообществам: запроси цену, средний охват рекламных публикаций, состав аудитории и доступные даты. Учитывай комиссии и налоги. Число подписчиков не подменяет охват рекламы. 4. Собери медиаплан по каналам, укажи источники, даты, географию и валюту. Отдели факты от прогнозов и гипотез. Используй прошлые кампании владельца, если они есть. Обнови бюджет и цену клика на основе медиаплана, сверяя клики с визитами. Конверсии без своих замеров оставь гипотезами для теста. Стартовые цифры книги не используй как рыночные. 5. Работай в копии. Меняй жёлтые ячейки, сохраняй формулы и авторство. Изменение логики или числа тарифов согласуй с владельцем. Разделяй выручку, вклад клиента и деньги на запуск; не считай часы менеджера и поддержки повторно в постоянном ФОТ. 6. Проверь формулы, нулевой бюджет, отток 0% и 100%, лаг демо и все способы продажи. Верни заполненный файл и объясни результат. Если Excel недоступен, посчитай в доступном инструменте и сделай сводку с картинкой. Запуск рекламы согласуй отдельно.
B14: Оплата помесячно за компанию. Стартовые цифры — модельные; годовой оплаты, налогов и переходов между тарифами здесь нет.
B16: Хороший расчёт начинается с разговора о вашем продукте, клиентах и способе продажи.
B17: Разобрать модель своего проекта → t.me/tribunska

Sheet Итог
A1: B2B SaaS • экономика запуска
A3: Сценарий: | B3: =IFERROR(CHOOSE(Допущения!$B$3,"Осторожный","Базовый","Сильный"),"Проверьте выбор") -> Базовый | D3: Продажи: | E3: =IFERROR(CHOOSE(Допущения!$B$4,"Самостоятельно","Через демо","Смешанные"),"Проверьте выбор") -> Смешанные
A5: За первые 12 месяцев | D5: Как читать цифры
A7: Новых платящих компаний | B7: =SUM(Деньги!B7:B18) -> 537.3 | D7: Стоимость привлечения включает рекламу и часы менеджера. В конце периода часть демо ещё ждёт оплаты — эти компании в продажи не попадают.
A8: Активных к концу периода | B8: =Деньги!C18 -> 416.47018
A9: Выручка за 12 месяцев, ₽ | B9: =SUM(Деньги!D7:D18) -> 22747109
A10: Выручка в 12-м месяце, ₽ | B10: =Деньги!D18 -> 3745696.9
A11: Средняя стоимость привлечения, ₽ | B11: =IF(B7=0,"Нет оплат",(SUM(Деньги!G7:H18))/B7) -> 4142.9369 | D11: Сравните стоимость привлечения с вкладом клиента ниже. Затем проверьте, сколько денег потребует запуск: прибыльный тариф и запуск без кассового разрыва — разные вопросы.
A12: Первый месяц с положительным потоком | B12: =IF(COUNTIF(Деньги!M7:M18,1)=0,"За 12 месяцев не достигнут","Месяц "&MATCH(1,Деньги!M7:M18,0)) -> Месяц 4
A13: Возврат вложенных денег | B13: =IF(COUNTIF(Деньги!N7:N18,1)=0,"За 12 месяцев не достигнут","Месяц "&MATCH(1,Деньги!N7:N18,0)) -> Месяц 7
A15: Максимальный дефицит, ₽ | B15: =MAX(Деньги!L6:L18) -> 2242686.7
A16: Запас на запуск, ₽ | B16: =B15*IF(AND(ISNUMBER(Допущения!$B$9),Допущения!$B$9>=0,Допущения!$B$9<=1),Допущения!$B$9,NA()) -> 448537.34 | D16: Ожидаемые компании могут быть дробными. Сценарий меняет цену клика, конверсию оплаты и отток, но не переписывает ваши тарифы.
A17: Денег на запуск с запасом, ₽ | B17: =B15+B16 -> 2691224
A18: Накопленный поток к концу, ₽ | B18: =Деньги!K18 -> 10532932
A21: Тариф | B21: Цена / месяц, ₽ | D21: Новых за год | E21: Активных в конце | F21: Привлечение, ₽ | G21: Вклад клиента, ₽ | H21: Вклад за вычетом привлечения, ₽
A22: =Допущения!$A$30 -> Старт | B22: =Допущения!$B$30 -> 4900 | D22: =SUMIF(Подписка!$B$6:$B$41,A22,Подписка!$F$6:$F$41) -> 420 | E22: =Подписка!G39 -> 317.69526 | F22: =IF(D22=0,"Нет оплат",(SUMIF(Привлечение!$B$6:$B$41,A22,Привлечение!$D$6:$D$41)+SUMIF(Привлечение!$B$6:$B$41,A22,Привлечение!$N$6:$N$41))/D22) -> 2500 | G22: =Подписка!E46 -> 21317.661 | H22: =IF(ISNUMBER(F22),G22-F22,"Нет оплат") -> 18817.661
A23: =Допущения!$A$31 -> Команда | B23: =Допущения!$B$31 -> 14900 | D23: =SUMIF(Подписка!$B$6:$B$41,A23,Подписка!$F$6:$F$41) -> 94.5 | E23: =Подписка!G40 -> 78.282241 | F23: =IF(D23=0,"Нет оплат",(SUMIF(Привлечение!$B$6:$B$41,A23,Привлечение!$D$6:$D$41)+SUMIF(Привлечение!$B$6:$B$41,A23,Привлечение!$N$6:$N$41))/D23) -> 7777.7778 | G23: =Подписка!E47 -> 67251.386 | H23: =IF(ISNUMBER(F23),G23-F23,"Нет оплат") -> 59473.608
A24: =Допущения!$A$32 -> Бизнес | B24: =Допущения!$B$32 -> 49900 | D24: =SUMIF(Подписка!$B$6:$B$41,A24,Подписка!$F$6:$F$41) -> 22.8 | E24: =Подписка!G41 -> 20.49268 | F24: =IF(D24=0,"Нет оплат",(SUMIF(Привлечение!$B$6:$B$41,A24,Привлечение!$D$6:$D$41)+SUMIF(Привлечение!$B$6:$B$41,A24,Привлечение!$N$6:$N$41))/D24) -> 19342.105 | G24: =Подписка!E48 -> 235844.43 | H24: =IF(ISNUMBER(F24),G24-F24,"Нет оплат") -> 216502.33
A26: ="Вклад клиента за "&Допущения!B16&" месяцев: выручка минус переменные затраты, с учётом оттока. Постоянные расходы — в общем потоке." -> Вклад клиента за 6 месяцев: выручка минус переменные затраты, с учётом оттока. Постоянные расходы — в общем потоке.
A28: Месяц | B28: Новых компаний | D28: Выручка, ₽ | E28: Реклама + менеджер, ₽ | F28: Поток, ₽ | G28: Накопленно, ₽ | H28: Дефицит, ₽
A29: Месяц 1 | B29: =Деньги!B7 -> 12.25 | D29: =Деньги!D7 -> 82525 | E29: =SUM(Деньги!G7:H7) -> 53000 | F29: =Деньги!J7 -> -391600.25 | G29: =Деньги!K7 -> -1841600.2 | H29: =Деньги!L7 -> 1841600.2
A30: Месяц 2 | B30: =Деньги!B8 -> 25.1 | D30: =Деньги!D8 -> 273234 | E30: =SUM(Деньги!G8:H8) -> 106000 | F30: =Деньги!J8 -> -293840.34 | G30: =Деньги!K8 -> -2135440.6 | H30: =Деньги!L8 -> 2135440.6
A31: Месяц 3 | B31: =Деньги!B9 -> 37.95 | D31: =Деньги!D9 -> 567327.54 | E31: =SUM(Деньги!G9:H9) -> 159000 | F31: =Деньги!J9 -> -107246.12 | G31: =Деньги!K9 -> -2242686.7 | H31: =Деньги!L9 -> 2242686.7
A32: Месяц 4 | B32: =Деньги!B10 -> 50.8 | D32: =Деньги!D10 -> 960242.18 | E32: =SUM(Деньги!G10:H10) -> 212000 | F32: =Деньги!J10 -> 164259.57 | G32: =Деньги!K10 -> -2078427.1 | H32: =Деньги!L10 -> 2242686.7
A33: Месяц 5 | B33: =Деньги!B11 -> 51.4 | D33: =Деньги!D11 -> 1365113 | E33: =SUM(Деньги!G11:H11) -> 212000 | F33: =Деньги!J11 -> 508546.38 | G33: =Деньги!K11 -> -1569880.8 | H33: =Деньги!L11 -> 2242686.7
A34: Месяц 6 | B34: =Деньги!B12 -> 51.4 | D34: =Деньги!D12 -> 1752153 | E34: =SUM(Деньги!G12:H12) -> 212000 | F34: =Деньги!J12 -> 841105.43 | G34: =Деньги!K12 -> -728775.33 | H34: =Деньги!L12 -> 2242686.7
A35: Месяц 7 | B35: =Деньги!B13 -> 51.4 | D35: =Деньги!D13 -> 2122234 | E35: =SUM(Деньги!G13:H13) -> 212000 | F35: =Деньги!J13 -> 1159086.6 | G35: =Деньги!K13 -> 430311.29 | H35: =Деньги!L13 -> 2242686.7
A36: Месяц 8 | B36: =Деньги!B14 -> 51.4 | D36: =Деньги!D14 -> 2476182 | E36: =SUM(Деньги!G14:H14) -> 212000 | F36: =Деньги!J14 -> 1463200.4 | G36: =Деньги!K14 -> 1893511.6 | H36: =Деньги!L14 -> 2242686.7
A37: Месяц 9 | B37: =Деньги!B15 -> 51.4 | D37: =Деньги!D15 -> 2814779.8 | E37: =SUM(Деньги!G15:H15) -> 212000 | F37: =Деньги!J15 -> 1754119.7 | G37: =Деньги!K15 -> 3647631.4 | H37: =Деньги!L15 -> 2242686.7
A38: Месяц 10 | B38: =Деньги!B16 -> 51.4 | D38: =Деньги!D16 -> 3138769 | E38: =SUM(Деньги!G16:H16) -> 212000 | F38: =Деньги!J16 -> 2032482.5 | G38: =Деньги!K16 -> 5680113.9 | H38: =Деньги!L16 -> 2242686.7
A39: Месяц 11 | B39: =Деньги!B17 -> 51.4 | D39: =Деньги!D17 -> 3448852.6 | E39: =SUM(Деньги!G17:H17) -> 212000 | F39: =Деньги!J17 -> 2298893.3 | G39: =Деньги!K17 -> 7979007.2 | H39: =Деньги!L17 -> 2242686.7
A40: Месяц 12 | B40: =Деньги!B18 -> 51.4 | D40: =Деньги!D18 -> 3745696.9 | E40: =SUM(Деньги!G18:H18) -> 212000 | F40: =Деньги!J18 -> 2553925 | G40: =Деньги!K18 -> 10532932 | H40: =Деньги!L18 -> 2242686.7
A42: =Допущения!A54
A43: Елизавета Трибунская • tribunska.ru

Sheet Допущения
A1: Допущения • три тарифа
A3: Сценарий (1–3) | B3: 2 | D3: Продажи: | E3: =IFERROR(CHOOSE(Допущения!$B$4,"Самостоятельно","Через демо","Смешанные"),"Проверьте выбор") -> Смешанные
A4: Способ продажи (1–3) | B4: 3 | D4: 1 — самостоятельно; 2 — демо с менеджером; 3 — два младших тарифа самостоятельно, старший через демо.
D5: Сценарии: 1 — осторожный, 2 — базовый, 3 — сильный.
A7: Стоимость рабочего часа, ₽ | B7: 1000 | D7: Часы менеджера, поддержки и подключения считаем отдельно от постоянной команды.
A8: Комиссия с оплат | B8: 0.01
A9: Запас к деньгам на запуск | B9: 0.2
A10: Разработка до запуска, ₽ | B10: 1200000 | D10: Все стартовые числа — авторские модельные допущения. Замените своими данными.
A11: Упаковка и материалы, ₽ | B11: 150000
A12: Исследование и подготовка, ₽ | B12: 100000
A13: Постоянная команда в месяц, ₽ | B13: 300000 | D13: Постоянные расходы учитываются каждый месяц, стартовые — только до запуска.
A14: Постоянный маркетинг в месяц, ₽ | B14: 70000
A15: Прочие постоянные расходы, ₽/мес. | B15: 30000
A16: Срок для оценки вклада клиента, мес. | B16: 6
A17: От демо до оплаты, полных месяцев | B17: 1
A22: Параметр сценария | B22: В расчёте | C22: Осторожный | D22: Базовый | E22: Сильный
A23: Цена клика: множитель | B23: =IF(AND(ISNUMBER($B$3),$B$3=INT($B$3),$B$3>=1,$B$3<=3,COUNT(INDEX(C23:E23,1,$B$3))=1,INDEX(C23:E23,1,$B$3)>0),INDEX(C23:E23,1,$B$3),NA()) -> 1 | C23: 1.25 | D23: 1 | E23: 0.85
A24: Конверсия в оплату: множитель | B24: =IF(AND(ISNUMBER($B$3),$B$3=INT($B$3),$B$3>=1,$B$3<=3,COUNT(INDEX(C24:E24,1,$B$3))=1,INDEX(C24:E24,1,$B$3)>=0),INDEX(C24:E24,1,$B$3),NA()) -> 1 | C24: 0.65 | D24: 1 | E24: 1.25
A25: Отток: множитель | B25: =IF(AND(ISNUMBER($B$3),$B$3=INT($B$3),$B$3>=1,$B$3<=3,COUNT(INDEX(C25:E25,1,$B$3))=1,INDEX(C25:E25,1,$B$3)>=0),INDEX(C25:E25,1,$B$3),NA()) -> 1 | C25: 1.3 | D25: 1 | E25: 0.8
A29: Тариф | B29: Цена за месяц, ₽ | C29: Доля бюджета | D29: Отток / мес. | E29: Хостинг / компания, ₽ | F29: Поддержка, ч/мес. | G29: Подключение, ч | H29: Цена клика, ₽ | I29: Визит → оплата | J29: Визит → заявка на демо | K29: Заявка → проведённое демо | L29: Демо → оплата | M29: Часов на демо | N29: Демо в расчёте
A30: Старт | B30: 4900 | C30: 0.5 | D30: 0.06 | E30: 300 | F30: 0.33 | G30: 0.5 | H30: 45 | I30: 0.018 | J30: 0.06 | K30: 0.7 | L30: 0.2 | M30: 0.75 | N30: =IF(AND(ISNUMBER($B$4),$B$4=INT($B$4),$B$4>=1,$B$4<=3),IF($B$4=1,0,IF($B$4=2,1,0)),NA()) -> 0
A31: Команда | B31: 14900 | C31: 0.35 | D31: 0.04 | E31: 1000 | F31: 1 | G31: 2 | H31: 70 | I31: 0.009 | J31: 0.05 | K31: 0.75 | L31: 0.25 | M31: 1 | N31: =IF(AND(ISNUMBER($B$4),$B$4=INT($B$4),$B$4>=1,$B$4<=3),IF($B$4=1,0,IF($B$4=2,1,0)),NA()) -> 0
A32: Бизнес | B32: 49900 | C32: 0.15 | D32: 0.025 | E32: 3500 | F32: 3 | G32: 6 | H32: 120 | I32: 0.004 | J32: 0.04 | K32: 0.8 | L32: 0.3 | M32: 1.5 | N32: =IF(AND(ISNUMBER($B$4),$B$4=INT($B$4),$B$4>=1,$B$4<=3),IF($B$4=1,0,IF($B$4=2,1,1)),NA()) -> 1
A34: Доля бюджета — распределение расходов на трафик между тарифами; сумма — 100%.
A35: Множитель конверсии влияет на самостоятельную покупку и оплату после демо; верх воронки демо задаётся отдельно.
A39: Месяц | B39: Рекламный бюджет, ₽
A40: Месяц 1 | B40: 50000
A41: Месяц 2 | B41: 100000
A42: Месяц 3 | B42: 150000
A43: Месяц 4 | B43: 200000
A44: Месяц 5 | B44: 200000
A45: Месяц 6 | B45: 200000
A46: Месяц 7 | B46: 200000
A47: Месяц 8 | B47: 200000
A48: Месяц 9 | B48: 200000
A49: Месяц 10 | B49: 200000
A50: Месяц 11 | B50: 200000
A51: Месяц 12 | B51: 200000
A54: =IF(IFERROR(AND(AND(ISNUMBER(B3),B3>0,B3=INT(B3),B3<=3),AND(ISNUMBER(B4),B4>0,B4=INT(B4),B4<=3),AND(ISNUMBER(B7),B7>=0),AND(ISNUMBER(B8),B8>=0,B8<=1),AND(ISNUMBER(B9),B9>=0,B9<=1),AND(ISNUMBER(B10),B10>=0),AND(ISNUMBER(B11),B11>=0),AND(ISNUMBER(B12),B12>=0),AND(ISNUMBER(B13),B13>=0),AND(ISNUMBER(B14),B14>=0),AND(ISNUMBER(B15),B15>=0),AND(ISNUMBER(B16),B16>0,B16=INT(B16),B16<=120),AND(ISNUMBER(B17),B17>=0,B17=INT(B17),B17<=12),AND(ISNUMBER(C23),C23>0),AND(ISNUMBER(D23),D23>0),AND(ISNUMBER(E23),E23>0),AND(ISNUMBER(C24),C24>=0),AND(ISNUMBER(D24),D24>=0),AND(ISNUMBER(E24),E24>=0),AND(ISNUMBER(C25),C25>=0),AND(ISNUMBER(D25),D25>=0),AND(ISNUMBER(E25),E25>=0),AND(ISNUMBER(B30),B30>0),AND(ISNUMBER(C30),C30>=0,C30<=1),AND(ISNUMBER(D30),D30>=0,D30<=1),AND(ISNUMBER(E30),E30>=0),AND(ISNUMBER(F30),F30>=0),AND(ISNUMBER(G30),G30>=0),AND(ISNUMBER(H30),H30>0),AND(ISNUMBER(I30),I30>=0,I30<=1),AND(ISNUMBER(J30),J30>=0,J30<=1),AND(ISNUMBER(K30),K30>=0,K30<=1),AND(ISNUMBER(L30),L30>=0,L30<=1),AND(ISNUMBER(M30),M30>=0),AND(ISNUMBER(B31),B31>0),AND(ISNUMBER(C31),C31>=0,C31<=1),AND(ISNUMBER(D31),D31>=0,D31<=1),AND(ISNUMBER(E31),E31>=0),AND(ISNUMBER(F31),F31>=0),AND(ISNUMBER(G31),G31>=0),AND(ISNUMBER(H31),H31>0),AND(ISNUMBER(I31),I31>=0,I31<=1),AND(ISNUMBER(J31),J31>=0,J31<=1),AND(ISNUMBER(K31),K31>=0,K31<=1),AND(ISNUMBER(L31),L31>=0,L31<=1),AND(ISNUMBER(M31),M31>=0),AND(ISNUMBER(B32),B32>0),AND(ISNUMBER(C32),C32>=0,C32<=1),AND(ISNUMBER(D32),D32>=0,D32<=1),AND(ISNUMBER(E32),E32>=0),AND(ISNUMBER(F32),F32>=0),AND(ISNUMBER(G32),G32>=0),AND(ISNUMBER(H32),H32>0),AND(ISNUMBER(I32),I32>=0,I32<=1),AND(ISNUMBER(J32),J32>=0,J32<=1),AND(ISNUMBER(K32),K32>=0,K32<=1),AND(ISNUMBER(L32),L32>=0,L32<=1),AND(ISNUMBER(M32),M32>=0),AND(ISNUMBER(B40),B40>=0),AND(ISNUMBER(B41),B41>=0),AND(ISNUMBER(B42),B42>=0),AND(ISNUMBER(B43),B43>=0),AND(ISNUMBER(B44),B44>=0),AND(ISNUMBER(B45),B45>=0),AND(ISNUMBER(B46),B46>=0),AND(ISNUMBER(B47),B47>=0),AND(ISNUMBER(B48),B48>=0),AND(ISNUMBER(B49),B49>=0),AND(ISNUMBER(B50),B50>=0),AND(ISNUMBER(B51),B51>=0),ABS(SUM(C30:C32)-1)<0.00000001,MAX(D30:D32)*B25<=1,MAX(I30:I32)*B24<=1,MAX(L30:L32)*B24<=1),FALSE),"","Проверьте вводные: красные ячейки, доли бюджета и конверсии с множителями.")

Sheet Привлечение
A1: Привлечение • самостоятельно или через демо
A3: Сценарий: | B3: =IFERROR(CHOOSE(Допущения!$B$3,"Осторожный","Базовый","Сильный"),"Проверьте выбор") -> Базовый | D3: Продажи: | E3: =IFERROR(CHOOSE(Допущения!$B$4,"Самостоятельно","Через демо","Смешанные"),"Проверьте выбор") -> Смешанные
A5: Месяц | B5: Тариф | C5: Через демо | D5: Трафик, ₽ | E5: Цена клика, ₽ | F5: Визиты | G5: Покупки сами | H5: Заявки на демо | I5: Демо проведены | J5: Будущие оплаты с этих демо | K5: Оплаты прошлых демо | L5: Новые компании | M5: Часы менеджера | N5: Менеджер, ₽
A6: Месяц 1 | B6: =Допущения!$A$30 -> Старт | C6: =Допущения!$N$30 -> 0 | D6: =IF(AND(COUNT(Допущения!$C$30:$C$32)=3,MIN(Допущения!$C$30:$C$32)>=0,MAX(Допущения!$C$30:$C$32)<=1,ABS(SUM(Допущения!$C$30:$C$32)-1)<0.00000001),IF(AND(ISNUMBER(Допущения!$B$40),Допущения!$B$40>=0),Допущения!$B$40,NA())*Допущения!$C$30,NA()) -> 25000 | E6: =IF(AND(ISNUMBER(Допущения!$H$30),Допущения!$H$30>0),Допущения!$H$30,NA())*Допущения!$B$23 -> 45 | F6: =D6/E6 -> 555.55556 | G6: =IF(C6=1,0,IF(IF(AND(ISNUMBER(Допущения!$I$30),Допущения!$I$30>=0,Допущения!$I$30<=1),Допущения!$I$30,NA())*Допущения!$B$24<=1,F6*IF(AND(ISNUMBER(Допущения!$I$30),Допущения!$I$30>=0,Допущения!$I$30<=1),Допущения!$I$30,NA())*Допущения!$B$24,NA())) -> 10 | H6: =IF(C6=0,0,F6*IF(AND(ISNUMBER(Допущения!$J$30),Допущения!$J$30>=0,Допущения!$J$30<=1),Допущения!$J$30,NA())) -> 0 | I6: =H6*IF(AND(ISNUMBER(Допущения!$K$30),Допущения!$K$30>=0,Допущения!$K$30<=1),Допущения!$K$30,NA()) -> 0 | J6: =IF(C6=0,0,IF(IF(AND(ISNUMBER(Допущения!$L$30),Допущения!$L$30>=0,Допущения!$L$30<=1),Допущения!$L$30,NA())*Допущения!$B$24<=1,I6*IF(AND(ISNUMBER(Допущения!$L$30),Допущения!$L$30>=0,Допущения!$L$30<=1),Допущения!$L$30,NA())*Допущения!$B$24,NA())) -> 0 | K6: =IF(1<=IF(AND(ISNUMBER(Допущения!$B$17),Допущения!$B$17>=0,Допущения!$B$17=INT(Допущения!$B$17),Допущения!$B$17<=12),Допущения!$B$17,NA()),0,INDEX($J$6:$J$41,(1-IF(AND(ISNUMBER(Допущения!$B$17),Допущения!$B$17>=0,Допущения!$B$17=INT(Допущения!$B$17),Допущения!$B$17<=12),Допущения!$B$17,NA())-1)*3+1)) -> 0 | L6: =G6+K6 -> 10 | M6: =I6*IF(AND(ISNUMBER(Допущения!$M$30),Допущения!$M$30>=0),Допущения!$M$30,NA()) -> 0 | N6: =M6*IF(AND(ISNUMBER(Допущения!$B$7),Допущения!$B$7>=0),Допущения!$B$7,NA()) -> 0
A7: Месяц 1 | B7: =Допущения!$A$31 -> Команда | C7: =Допущения!$N$31 -> 0 | D7: =IF(AND(COUNT(Допущения!$C$30:$C$32)=3,MIN(Допущения!$C$30:$C$32)>=0,MAX(Допущения!$C$30:$C$32)<=1,ABS(SUM(Допущения!$C$30:$C$32)-1)<0.00000001),IF(AND(ISNUMBER(Допущения!$B$40),Допущения!$B$40>=0),Допущения!$B$40,NA())*Допущения!$C$31,NA()) -> 17500 | E7: =IF(AND(ISNUMBER(Допущения!$H$31),Допущения!$H$31>0),Допущения!$H$31,NA())*Допущения!$B$23 -> 70 | F7: =D7/E7 -> 250 | G7: =IF(C7=1,0,IF(IF(AND(ISNUMBER(Допущения!$I$31),Допущения!$I$31>=0,Допущения!$I$31<=1),Допущения!$I$31,NA())*Допущения!$B$24<=1,F7*IF(AND(ISNUMBER(Допущения!$I$31),Допущения!$I$31>=0,Допущения!$I$31<=1),Допущения!$I$31,NA())*Допущения!$B$24,NA())) -> 2.25 | H7: =IF(C7=0,0,F7*IF(AND(ISNUMBER(Допущения!$J$31),Допущения!$J$31>=0,Допущения!$J$31<=1),Допущения!$J$31,NA())) -> 0 | I7: =H7*IF(AND(ISNUMBER(Допущения!$K$31),Допущения!$K$31>=0,Допущения!$K$31<=1),Допущения!$K$31,NA()) -> 0 | J7: =IF(C7=0,0,IF(IF(AND(ISNUMBER(Допущения!$L$31),Допущения!$L$31>=0,Допущения!$L$31<=1),Допущения!$L$31,NA())*Допущения!$B$24<=1,I7*IF(AND(ISNUMBER(Допущения!$L$31),Допущения!$L$31>=0,Допущения!$L$31<=1),Допущения!$L$31,NA())*Допущения!$B$24,NA())) -> 0 | K7: =IF(1<=IF(AND(ISNUMBER(Допущения!$B$17),Допущения!$B$17>=0,Допущения!$B$17=INT(Допущения!$B$17),Допущения!$B$17<=12),Допущения!$B$17,NA()),0,INDEX($J$6:$J$41,(1-IF(AND(ISNUMBER(Допущения!$B$17),Допущения!$B$17>=0,Допущения!$B$17=INT(Допущения!$B$17),Допущения!$B$17<=12),Допущения!$B$17,NA())-1)*3+2)) -> 0 | L7: =G7+K7 -> 2.25 | M7: =I7*IF(AND(ISNUMBER(Допущения!$M$31),Допущения!$M$31>=0),Допущения!$M$31,NA()) -> 0 | N7: =M7*IF(AND(ISNUMBER(Допущения!$B$7),Допущения!$B$7>=0),Допущения!$B$7,NA()) -> 0
A8: Месяц 1 | B8: =Допущения!$A$32 -> Бизнес | C8: =Допущения!$N$32 -> 1 | D8: =IF(AND(COUNT(Допущения!$C$30:$C$32)=3,MIN(Допущения!$C$30:$C$32)>=0,MAX(Допущения!$C$30:$C$32)<=1,ABS(SUM(Допущения!$C$30:$C$32)-1)<0.00000001),IF(AND(ISNUMBER(Допущения!$B$40),Допущения!$B$40>=0),Допущения!$B$40,NA())*Допущения!$C$32,NA()) -> 7500 | E8: =IF(AND(ISNUMBER(Допущения!$H$32),Допущения!$H$32>0),Допущения!$H$32,NA())*Допущения!$B$23 -> 120 | F8: =D8/E8 -> 62.5 | G8: =IF(C8=1,0,IF(IF(AND(ISNUMBER(Допущения!$I$32),Допущения!$I$32>=0,Допущения!$I$32<=1),Допущения!$I$32,NA())*Допущения!$B$24<=1,F8*IF(AND(ISNUMBER(Допущения!$I$32),Допущения!$I$32>=0,Допущения!$I$32<=1),Допущения!$I$32,NA())*Допущения!$B$24,NA())) -> 0 | H8: =IF(C8=0,0,F8*IF(AND(ISNUMBER(Допущения!$J$32),Допущения!$J$32>=0,Допущения!$J$32<=1),Допущения!$J$32,NA())) -> 2.5 | I8: =H8*IF(AND(ISNUMBER(Допущения!$K$32),Допущения!$K$32>=0,Допущения!$K$32<=1),Допущения!$K$32,NA()) -> 2 | J8: =IF(C8=0,0,IF(IF(AND(ISNUMBER(Допущения!$L$32),Допущения!$L$32>=0,Допущения!$L$32<=1),Допущения!$L$32,NA())*Допущения!$B$24<=1,I8*IF(AND(ISNUMBER(Допущения!$L$32),Допущения!$L$32>=0,Допущения!$L$32<=1),Допущения!$L$32,NA())*Допущения!$B$24,NA())) -> 0.6 | K8: =IF(1<=IF(AND(ISNUMBER(Допущения!$B$17),Допущения!$B$17>=0,Допущения!$B$17=INT(Допущения!$B$17),Допущения!$B$17<=12),Допущения!$B$17,NA()),0,INDEX($J$6:$J$41,(1-IF(AND(ISNUMBER(Допущения!$B$17),Допущения!$B$17>=0,Допущения!$B$17=INT(Допущения!$B$17),Допущения!$B$17<=12),Допущения!$B$17,NA())-1)*3+3)) -> 0 | L8: =G8+K8 -> 0 | M8: =I8*IF(AND(ISNUMBER(Допущения!$M$32),Допущения!$M$32>=0),Допущения!$M$32,NA()) -> 3 | N8: =M8*IF(AND(ISNUMBER(Допущения!$B$7),Допущения!$B$7>=0),Допущения!$B$7,NA()) -> 3000
A9: Месяц 2 | B9: =Допущения!$A$30 -> Старт | C9: =Допущения!$N$30 -> 0 | D9: =IF(AND(COUNT(Допущения!$C$30:$C$32)=3,MIN(Допущения!$C$30:$C$32)>=0,MAX(Допущения!$C$30:$C$32)<=1,ABS(SUM(Допущения!$C$30:$C$32)-1)<0.00000001),IF(AND(ISNUMBER(Допущения!$B$41),Допущения!$B$41>=0),Допущения!$B$41,NA())*Допущения!$C$30,NA()) -> 50000 | E9: =IF(AND(ISNUMBER(Допущения!$H$30),Допущения!$H$30>0),Допущения!$H$30,NA())*Допущения!$B$23 -> 45 | F9: =D9/E9 -> 1111.1111 | G9: =IF(C9=1,0,IF(IF(AND(ISNUMBER(Допущения!$I$30),Допущения!$I$30>=0,Допущения!$I$30<=1),Допущения!$I$30,NA())*Допущения!$B$24<=1,F9*IF(AND(ISNUMBER(Допущения!$I$30),Допущения!$I$30>=0,Допущения!$I$30<=1),Допущения!$I$30,NA())*Допущения!$B$24,NA())) -> 20 | H9: =IF(C9=0,0,F9*IF(AND(ISNUMBER(Допущения!$J$30),Допущения!$J$30>=0,Допущения!$J$30<=1),Допущения!$J$30,NA())) -> 0 | I9: =H9*IF(AND(ISNUMBER(Допущения!$K$30),Допущения!$K$30>=0,Допущения!$K$30<=1),Допущения!$K$30,NA()) -> 0 | J9: =IF(C9=0,0,IF(IF(AND(ISNUMBER(Допущения!$L$30),Допущения!$L$30>=0,Допущения!$L$30<=1),Допущения!$L$30,NA())*Допущения!$B$24<=1,I9*IF(AND(ISNUMBER(Допущения!$L$30),Допущения!$L$30>=0,Допущения!$L$30<=1),Допущения!$L$30,NA())*Допущения!$B$24,NA())) -> 0 | K9: =IF(2<=IF(AND(ISNUMBER(Допущения!$B$17),Допущения!$B$17>=0,Допущения!$B$17=INT(Допущения!$B$17),Допущения!$B$17<=12),Допущения!$B$17,NA()),0,INDEX($J$6:$J$41,(2-IF(AND(ISNUMBER(Допущения!$B$17),Допущения!$B$17>=0,Допущения!$B$17=INT(Допущения!$B$17),Допущения!$B$17<=12),Допущения!$B$17,NA())-1)*3+1)) -> 0 | L9: =G9+K9 -> 20 | M9: =I9*IF(AND(ISNUMBER(Допущения!$M$30),Допущения!$M$30>=0),Допущения!$M$30,NA()) -> 0 | N9: =M9*IF(AND(ISNUMBER(Допущения!$B$7),Допущения!$B$7>=0),Допущения!$B$7,NA()) -> 0
A10: Месяц 2 | B10: =Допущения!$A$31 -> Команда | C10: =Допущения!$N$31 -> 0 | D10: =IF(AND(COUNT(Допущения!$C$30:$C$32)=3,MIN(Допущения!$C$30:$C$32)>=0,MAX(Допущения!$C$30:$C$32)<=1,ABS(SUM(Допущения!$C$30:$C$32)-1)<0.00000001),IF(AND(ISNUMBER(Допущения!$B$41),Допущения!$B$41>=0),Допущения!$B$41,NA())*Допущения!$C$31,NA()) -> 35000 | E10: =IF(AND(ISNUMBER(Допущения!$H$31),Допущения!$H$31>0),Допущения!$H$31,NA())*Допущения!$B$23 -> 70 | F10: =D10/E10 -> 500 | G10: =IF(C10=1,0,IF(IF(AND(ISNUMBER(Допущения!$I$31),Допущения!$I$31>=0,Допущения!$I$31<=1),Допущения!$I$31,NA())*Допущения!$B$24<=1,F10*IF(AND(ISNUMBER(Допущения!$I$31),Допущения!$I$31>=0,Допущения!$I$31<=1),Допущения!$I$31,NA())*Допущения!$B$24,NA())) -> 4.5 | H10: =IF(C10=0,0,F10*IF(AND(ISNUMBER(Допущения!$J$31),Допущения!$J$31>=0,Допущения!$J$31<=1),Допущения!$J$31,NA())) -> 0 | I10: =H10*IF(AND(ISNUMBER(Допущения!$K$31),Допущения!$K$31>=0,Допущения!$K$31<=1),Допущения!$K$31,NA()) -> 0 | J10: =IF(C10=0,0,IF(IF(AND(ISNUMBER(Допущения!$L$31),Допущения!$L$31>=0,Допущения!$L$31<=1),Допущения!$L$31,NA())*Допущения!$B$24<=1,I10*IF(AND(ISNUMBER(Допущения!$L$31),Допущения!$L$31>=0,Допущения!$L$31<=1),Допущения!$L$31,NA())*Допущения!$B$24,NA())) -> 0 | K10: =IF(2<=IF(AND(ISNUMBER(Допущения!$B$17),Допущения!$B$17>=0,Допущения!$B$17=INT(Допущения!$B$17),Допущения!$B$17<=12),Допущения!$B$17,NA()),0,INDEX($J$6:$J$41,(2-IF(AND(ISNUMBER(Допущения!$B$17),Допущения!$B$17>=0,Допущения!$B$17=INT(Допущения!$B$17),Допущения!$B$17<=12),Допущения!$B$17,NA())-1)*3+2)) -> 0 | L10: =G10+K10 -> 4.5 | M10: =I10*IF(AND(ISNUMBER(Допущения!$M$31),Допущения!$M$31>=0),Допущения!$M$31,NA()) -> 0 | N10: =M10*IF(AND(ISNUMBER(Допущения!$B$7),Допущения!$B$7>=0),Допущения!$B$7,NA()) -> 0
A11: Месяц 2 | B11: =Допущения!$A$32 -> Бизнес | C11: =Допущения!$N$32 -> 1 | D11: =IF(AND(COUNT(Допущения!$C$30:$C$32)=3,MIN(Допущения!$C$30:$C$32)>=0,MAX(Допущения!$C$30:$C$32)<=1,ABS(SUM(Допущения!$C$30:$C$32)-1)<0.00000001),IF(AND(ISNUMBER(Допущения!$B$41),Допущения!$B$41>=0),Допущения!$B$41,NA())*Допущения!$C$32,NA()) -> 15000 | E11: =IF(AND(ISNUMBER(Допущения!$H$32),Допущения!$H$32>0),Допущения!$H$32,NA())*Допущения!$B$23 -> 120 | F11: =D11/E11 -> 125 | G11: =IF(C11=1,0,IF(IF(AND(ISNUMBER(Допущения!$I$32),Допущения!$I$32>=0,Допущения!$I$32<=1),Допущения!$I$32,NA())*Допущения!$B$24<=1,F11*IF(AND(ISNUMBER(Допущения!$I$32),Допущения!$I$32>=0,Допущения!$I$32<=1),Допущения!$I$32,NA())*Допущения!$B$24,NA())) -> 0 | H11: =IF(C11=0,0,F11*IF(AND(ISNUMBER(Допущения!$J$32),Допущения!$J$32>=0,Допущения!$J$32<=1),Допущения!$J$32,NA())) -> 5 | I11: =H11*IF(AND(ISNUMBER(Допущения!$K$32),Допущения!$K$32>=0,Допущения!$K$32<=1),Допущения!$K$32,NA()) -> 4 | J11: =IF(C11=0,0,IF(IF(AND(ISNUMBER(Допущения!$L$32),Допущения!$L$32>=0,Допущения!$L$32<=1),Допущения!$L$32,NA())*Допущения!$B$24<=1,I11*IF(AND(ISNUMBER(Допущения!$L$32),Допущения!$L$32>=0,Допущения!$L$32<=1),Допущения!$L$32,NA())*Допущения!$B$24,NA())) -> 1.2 | K11: =IF(2<=IF(AND(ISNUMBER(Допущения!$B$17),Допущения!$B$17>=0,Допущения!$B$17=INT(Допущения!$B$17),Допущения!$B$17<=12),Допущения!$B$17,NA()),0,INDEX($J$6:$J$41,(2-IF(AND(ISNUMBER(Допущения!$B$17),Допущения!$B$17>=0,Допущения!$B$17=INT(Допущения!$B$17),Допущения!$B$17<=12),Допущения!$B$17,NA())-1)*3+3)) -> 0.6 | L11: =G11+K11 -> 0.6 | M11: =I11*IF(AND(ISNUMBER(Допущения!$M$32),Допущения!$M$32>=0),Допущения!$M$32,NA()) -> 6 | N11: =M11*IF(AND(ISNUMBER(Допущения!$B$7),Допущения!$B$7>=0),Допущения!$B$7,NA()) -> 6000
A12: Месяц 3 | B12: =Допущения!$A$30 -> Старт | C12: =Допущения!$N$30 -> 0 | D12: =IF(AND(COUNT(Допущения!$C$30:$C$32)=3,MIN(Допущения!$C$30:$C$32)>=0,MAX(Допущения!$C$30:$C$32)<=1,ABS(SUM(Допущения!$C$30:$C$32)-1)<0.00000001),IF(AND(ISNUMBER(Допущения!$B$42),Допущения!$B$42>=0),Допущения!$B$42,NA())*Допущения!$C$30,NA()) -> 75000 | E12: =IF(AND(ISNUMBER(Допущения!$H$30),Допущения!$H$30>0),Допущения!$H$30,NA())*Допущения!$B$23 -> 45 | F12: =D12/E12 -> 1666.6667 | G12: =IF(C12=1,0,IF(IF(AND(ISNUMBER(Допущения!$I$30),Допущения!$I$30>=0,Допущения!$I$30<=1),Допущения!$I$30,NA())*Допущения!$B$24<=1,F12*IF(AND(ISNUMBER(Допущения!$I$30),Допущения!$I$30>=0,Допущения!$I$30<=1),Допущения!$I$30,NA())*Допущения!$B$24,NA())) -> 30 | H12: =IF(C12=0,0,F12*IF(AND(ISNUMBER(Допущения!$J$30),Допущения!$J$30>=0,Допущения!$J$30<=1),Допущения!$J$30,NA())) -> 0 | I12: =H12*IF(AND(ISNUMBER(Допущения!$K$30),Допущения!$K$30>=0,Допущения!$K$30<=1),Допущения!$K$30,NA()) -> 0 | J12: =IF(C12=0,0,IF(IF(AND(ISNUMBER(Допущения!$L$30),Допущения!$L$30>=0,Допущения!$L$30<=1),Допущения!$L$30,NA())*Допущения!$B$24<=1,I12*IF(AND(ISNUMBER(Допущения!$L$30),Допущения!$L$30>=0,Допущения!$L$30<=1),Допущения!$L$30,NA())*Допущения!$B$24,NA())) -> 0 | K12: =IF(3<=IF(AND(ISNUMBER(Допущения!$B$17),Допущения!$B$17>=0,Допущения!$B$17=INT(Допущения!$B$17),Допущения!$B$17<=12),Допущения!$B$17,NA()),0,INDEX($J$6:$J$41,(3-IF(AND(ISNUMBER(Допущения!$B$17),Допущения!$B$17>=0,Допущения!$B$17=INT(Допущения!$B$17),Допущения!$B$17<=12),Допущения!$B$17,NA())-1)*3+1)) -> 0 | L12: =G12+K12 -> 30 | M12: =I12*IF(AND(ISNUMBER(Допущения!$M$30),Допущения!$M$30>=0),Допущения!$M$30,NA()) -> 0 | N12: =M12*IF(AND(ISNUMBER(Допущения!$B$7),Допущения!$B$7>=0),Допущения!$B$7,NA()) -> 0
A13: Месяц 3 | B13: =Допущения!$A$31 -> Команда | C13: =Допущения!$N$31 -> 0 | D13: =IF(AND(COUNT(Допущения!$C$30:$C$32)=3,MIN(Допущения!$C$30:$C$32)>=0,MAX(Допущения!$C$30:$C$32)<=1,ABS(SUM(Допущения!$C$30:$C$32)-1)<0.00000001),IF(AND(ISNUMBER(Допущения!$B$42),Допущения!$B$42>=0),Допущения!$B$42,NA())*Допущения!$C$31,NA()) -> 52500 | E13: =IF(AND(ISNUMBER(Допущения!$H$31),Допущения!$H$31>0),Допущения!$H$31,NA())*Допущения!$B$23 -> 70 | F13: =D13/E13 -> 750 | G13: =IF(C13=1,0,IF(IF(AND(ISNUMBER(Допущения!$I$31),Допущения!$I$31>=0,Допущения!$I$31<=1),Допущения!$I$31,NA())*Допущения!$B$24<=1,F13*IF(AND(ISNUMBER(Допущения!$I$31),Допущения!$I$31>=0,Допущения!$I$31<=1),Допущения!$I$31,NA())*Допущения!$B$24,NA())) -> 6.75 | H13: =IF(C13=0,0,F13*IF(AND(ISNUMBER(Допущения!$J$31),Допущения!$J$31>=0,Допущения!$J$31<=1),Допущения!$J$31,NA())) -> 0 | I13: =H13*IF(AND(ISNUMBER(Допущения!$K$31),Допущения!$K$31>=0,Допущения!$K$31<=1),Допущения!$K$31,NA()) -> 0 | J13: =IF(C13=0,0,IF(IF(AND(ISNUMBER(Допущения!$L$31),Допущения!$L$31>=0,Допущения!$L$31<=1),Допущения!$L$31,NA())*Допущения!$B$24<=1,I13*IF(AND(ISNUMBER(Допущения!$L$31),Допущения!$L$31>=0,Допущения!$L$31<=1),Допущения!$L$31,NA())*Допущения!$B$24,NA())) -> 0 | K13: =IF(3<=IF(AND(ISNUMBER(Допущения!$B$17),Допущения!$B$17>=0,Допущения!$B$17=INT(Допущения!$B$17),Допущения!$B$17<=12),Допущения!$B$17,NA()),0,INDEX($J$6:$J$41,(3-IF(AND(ISNUMBER(Допущения!$B$17),Допущения!$B$17>=0,Допущения!$B$17=INT(Допущения!$B$17),Допущения!$B$17<=12),Допущения!$B$17,NA())-1)*3+2)) -> 0 | L13: =G13+K13 -> 6.75 | M13: =I13*IF(AND(ISNUMBER(Допущения!$M$31),Допущения!$M$31>=0),Допущения!$M$31,NA()) -> 0 | N13: =M13*IF(AND(ISNUMBER(Допущения!$B$7),Допущения!$B$7>=0),Допущения!$B$7,NA()) -> 0
A14: Месяц 3 | B14: =Допущения!$A$32 -> Бизнес | C14: =Допущения!$N$32 -> 1 | D14: =IF(AND(COUNT(Допущения!$C$30:$C$32)=3,MIN(Допущения!$C$30:$C$32)>=0,MAX(Допущения!$C$30:$C$32)<=1,ABS(SUM(Допущения!$C$30:$C$32)-1)<0.00000001),IF(AND(ISNUMBER(Допущения!$B$42),Допущения!$B$42>=0),Допущения!$B$42,NA())*Допущения!$C$32,NA()) -> 22500 | E14: =IF(AND(ISNUMBER(Допущения!$H$32),Допущения!$H$32>0),Допущения!$H$32,NA())*Допущения!$B$23 -> 120 | F14: =D14/E14 -> 187.5 | G14: =IF(C14=1,0,IF(IF(AND(ISNUMBER(Допущения!$I$32),Допущения!$I$32>=0,Допущения!$I$32<=1),Допущения!$I$32,NA())*Допущения!$B$24<=1,F14*IF(AND(ISNUMBER(Допущения!$I$32),Допущения!$I$32>=0,Допущения!$I$32<=1),Допущения!$I$32,NA())*Допущения!$B$24,NA())) -> 0 | H14: =IF(C14=0,0,F14*IF(AND(ISNUMBER(Допущения!$J$32),Допущения!$J$32>=0,Допущения!$J$32<=1),Допущения!$J$32,NA())) -> 7.5 | I14: =H14*IF(AND(ISNUMBER(Допущения!$K$32),Допущения!$K$32>=0,Допущения!$K$32<=1),Допущения!$K$32,NA()) -> 6 | J14: =IF(C14=0,0,IF(IF(AND(ISNUMBER(Допущения!$L$32),Допущения!$L$32>=0,Допущения!$L$32<=1),Допущения!$L$32,NA())*Допущения!$B$24<=1,I14*IF(AND(ISNUMBER(Допущения!$L$32),Допущения!$L$32>=0,Допущения!$L$32<=1),Допущения!$L$32,NA())*Допущения!$B$24,NA())) -> 1.8 | K14: =IF(3<=IF(AND(ISNUMBER(Допущения!$B$17),Допущения!$B$17>=0,Допущения!$B$17=INT(Допущения!$B$17),Допущения!$B$17<=12),Допущения!$B$17,NA()),0,INDEX($J$6:$J$41,(3-IF(AND(ISNUMBER(Допущения!$B$17),Допущения!$B$17>=0,Допущения!$B$17=INT(Допущения!$B$17),Допущения!$B$17<=12),Допущения!$B$17,NA())-1)*3+3)) -> 1.2 | L14: =G14+K14 -> 1.2 | M14: =I14*IF(AND(ISNUMBER(Допущения!$M$32),Допущения!$M$32>=0),Допущения!$M$32,NA()) -> 9 | N14: =M14*IF(AND(ISNUMBER(Допущения!$B$7),Допущения!$B$7>=0),Допущения!$B$7,NA()) -> 9000
A15: Месяц 4 | B15: =Допущения!$A$30 -> Старт | C15: =Допущения!$N$30 -> 0 | D15: =IF(AND(COUNT(Допущения!$C$30:$C$32)=3,MIN(Допущения!$C$30:$C$32)>=0,MAX(Допущения!$C$30:$C$32)<=1,ABS(SUM(Допущения!$C$30:$C$32)-1)<0.00000001),IF(AND(ISNUMBER(Допущения!$B$43),Допущения!$B$43>=0),Допущения!$B$43,NA())*Допущения!$C$30,NA()) -> 100000 | E15: =IF(AND(ISNUMBER(Допущения!$H$30),Допущения!$H$30>0),Допущения!$H$30,NA())*Допущения!$B$23 -> 45 | F15: =D15/E15 -> 2222.2222 | G15: =IF(C15=1,0,IF(IF(AND(ISNUMBER(Допущения!$I$30),Допущения!$I$30>=0,Допущения!$I$30<=1),Допущения!$I$30,NA())*Допущения!$B$24<=1,F15*IF(AND(ISNUMBER(Допущения!$I$30),Допущения!$I$30>=0,Допущения!$I$30<=1),Допущения!$I$30,NA())*Допущения!$B$24,NA())) -> 40 | H15: =IF(C15=0,0,F15*IF(AND(ISNUMBER(Допущения!$J$30),Допущения!$J$30>=0,Допущения!$J$30<=1),Допущения!$J$30,NA())) -> 0 | I15: =H15*IF(AND(ISNUMBER(Допущения!$K$30),Допущения!$K$30>=0,Допущения!$K$30<=1),Допущения!$K$30,NA()) -> 0 | J15: =IF(C15=0,0,IF(IF(AND(ISNUMBER(Допущения!$L$30),Допущения!$L$30>=0,Допущения!$L$30<=1),Допущения!$L$30,NA())*Допущения!$B$24<=1,I15*IF(AND(ISNUMBER(Допущения!$L$30),Допущения!$L$30>=0,Допущения!$L$30<=1),Допущения!$L$30,NA())*Допущения!$B$24,NA())) -> 0 | K15: =IF(4<=IF(AND(ISNUMBER(Допущения!$B$17),Допущения!$B$17>=0,Допущения!$B$17=INT(Допущения!$B$17),Допущения!$B$17<=12),Допущения!$B$17,NA()),0,INDEX($J$6:$J$41,(4-IF(AND(ISNUMBER(Допущения!$B$17),Допущения!$B$17>=0,Допущения!$B$17=INT(Допущения!$B$17),Допущения!$B$17<=12),Допущения!$B$17,NA())-1)*3+1)) -> 0 | L15: =G15+K15 -> 40 | M15: =I15*IF(AND(ISNUMBER(Допущения!$M$30),Допущения!$M$30>=0),Допущения!$M$30,NA()) -> 0 | N15: =M15*IF(AND(ISNUMBER(Допущения!$B$7),Допущения!$B$7>=0),Допущения!$B$7,NA()) -> 0
A16: Месяц 4 | B16: =Допущения!$A$31 -> Команда | C16: =Допущения!$N$31 -> 0 | D16: =IF(AND(COUNT(Допущения!$C$30:$C$32)=3,MIN(Допущения!$C$30:$C$32)>=0,MAX(Допущения!$C$30:$C$32)<=1,ABS(SUM(Допущения!$C$30:$C$32)-1)<0.00000001),IF(AND(ISNUMBER(Допущения!$B$43),Допущения!$B$43>=0),Допущения!$B$43,NA())*Допущения!$C$31,NA()) -> 70000 | E16: =IF(AND(ISNUMBER(Допущения!$H$31),Допущения!$H$31>0),Допущения!$H$31,NA())*Допущения!$B$23 -> 70 | F16: =D16/E16 -> 1000 | G16: =IF(C16=1,0,IF(IF(AND(ISNUMBER(Допущения!$I$31),Допущения!$I$31>=0,Допущения!$I$31<=1),Допущения!$I$31,NA())*Допущения!$B$24<=1,F16*IF(AND(ISNUMBER(Допущения!$I$31),Допущения!$I$31>=0,Допущения!$I$31<=1),Допущения!$I$31,NA())*Допущения!$B$24,NA())) -> 9 | H16: =IF(C16=0,0,F16*IF(AND(ISNUMBER(Допущения!$J$31),Допущения!$J$31>=0,Допущения!$J$31<=1),Допущения!$J$31,NA())) -> 0 | I16: =H16*IF(AND(ISNUMBER(Допущения!$K$31),Допущения!$K$31>=0,Допущения!$K$31<=1),Допущения!$K$31,NA()) -> 0 | J16: =IF(C16=0,0,IF(IF(AND(ISNUMBER(Допущения!$L$31),Допущения!$L$31>=0,Допущения!$L$31<=1),Допущения!$L$31,NA())*Допущения!$B$24<=1,I16*IF(AND(ISNUMBER(Допущения!$L$31),Допущения!$L$31>=0,Допущения!$L$31<=1),Допущения!$L$31,NA())*Допущения!$B$24,NA())) -> 0 | K16: =IF(4<=IF(AND(ISNUMBER(Допущения!$B$17),Допущения!$B$17>=0,Допущения!$B$17=INT(Допущения!$B$17),Допущения!$B$17<=12),Допущения!$B$17,NA()),0,INDEX($J$6:$J$41,(4-IF(AND(ISNUMBER(Допущения!$B$17),Допущения!$B$17>=0,Допущения!$B$17=INT(Допущения!$B$17),Допущения!$B$17<=12),Допущения!$B$17,NA())-1)*3+2)) -> 0 | L16: =G16+K16 -> 9 | M16: =I16*IF(AND(ISNUMBER(Допущения!$M$31),Допущения!$M$31>=0),Допущения!$M$31,NA()) -> 0 | N16: =M16*IF(AND(ISNUMBER(Допущения!$B$7),Допущения!$B$7>=0),Допущения!$B$7,NA()) -> 0
A17: Месяц 4 | B17: =Допущения!$A$32 -> Бизнес | C17: =Допущения!$N$32 -> 1 | D17: =IF(AND(COUNT(Допущения!$C$30:$C$32)=3,MIN(Допущения!$C$30:$C$32)>=0,MAX(Допущения!$C$30:$C$32)<=1,ABS(SUM(Допущения!$C$30:$C$32)-1)<0.00000001),IF(AND(ISNUMBER(Допущения!$B$43),Допущения!$B$43>=0),Допущения!$B$43,NA())*Допущения!$C$32,NA()) -> 30000 | E17: =IF(AND(ISNUMBER(Допущения!$H$32),Допущения!$H$32>0),Допущения!$H$32,NA())*Допущения!$B$23 -> 120 | F17: =D17/E17 -> 250 | G17: =IF(C17=1,0,IF(IF(AND(ISNUMBER(Допущения!$I$32),Допущения!$I$32>=0,Допущения!$I$32<=1),Допущения!$I$32,NA())*Допущения!$B$24<=1,F17*IF(AND(ISNUMBER(Допущения!$I$32),Допущения!$I$32>=0,Допущения!$I$32<=1),Допущения!$I$32,NA())*Допущения!$B$24,NA())) -> 0 | H17: =IF(C17=0,0,F17*IF(AND(ISNUMBER(Допущения!$J$32),Допущения!$J$32>=0,Допущения!$J$32<=1),Допущения!$J$32,NA())) -> 10 | I17: =H17*IF(AND(ISNUMBER(Допущения!$K$32),Допущения!$K$32>=0,Допущения!$K$32<=1),Допущения!$K$32,NA()) -> 8 | J17: =IF(C17=0,0,IF(IF(AND(ISNUMBER(Допущения!$L$32),Допущения!$L$32>=0,Допущения!$L$32<=1),Допущения!$L$32,NA())*Допущения!$B$24<=1,I17*IF(AND(ISNUMBER(Допущения!$L$32),Допущения!$L$32>=0,Допущения!$L$32<=1),Допущения!$L$32,NA())*Допущения!$B$24,NA())) -> 2.4 | K17: =IF(4<=IF(AND(ISNUMBER(Допущения!$B$17),Допущения!$B$17>=0,Допущения!$B$17=INT(Допущения!$B$17),Допущения!$B$17<=12),Допущения!$B$17,NA()),0,INDEX($J$6:$J$41,(4-IF(AND(ISNUMBER(Допущения!$B$17),Допущения!$B$17>=0,Допущения!$B$17=INT(Допущения!$B$17),Допущения!$B$17<=12),Допущения!$B$17,NA())-1)*3+3)) -> 1.8 | L17: =G17+K17 -> 1.8 | M17: =I17*IF(AND(ISNUMBER(Допущения!$M$32),Допущения!$M$32>=0),Допущения!$M$32,NA()) -> 12 | N17: =M17*IF(AND(ISNUMBER(Допущения!$B$7),Допущения!$B$7>=0),Допущения!$B$7,NA()) -> 12000
A18: Месяц 5 | B18: =Допущения!$A$30 -> Старт | C18: =Допущения!$N$30 -> 0 | D18: =IF(AND(COUNT(Допущения!$C$30:$C$32)=3,MIN(Допущения!$C$30:$C$32)>=0,MAX(Допущения!$C$30:$C$32)<=1,ABS(SUM(Допущения!$C$30:$C$32)-1)<0.00000001),IF(AND(ISNUMBER(Допущения!$B$44),Допущения!$B$44>=0),Допущения!$B$44,NA())*Допущения!$C$30,NA()) -> 100000 | E18: =IF(AND(ISNUMBER(Допущения!$H$30),Допущения!$H$30>0),Допущения!$H$30,NA())*Допущения!$B$23 -> 45 | F18: =D18/E18 -> 2222.2222 | G18: =IF(C18=1,0,IF(IF(AND(ISNUMBER(Допущения!$I$30),Допущения!$I$30>=0,Допущения!$I$30<=1),Допущения!$I$30,NA())*Допущения!$B$24<=1,F18*IF(AND(ISNUMBER(Допущения!$I$30),Допущения!$I$30>=0,Допущения!$I$30<=1),Допущения!$I$30,NA())*Допущения!$B$24,NA())) -> 40 | H18: =IF(C18=0,0,F18*IF(AND(ISNUMBER(Допущения!$J$30),Допущения!$J$30>=0,Допущения!$J$30<=1),Допущения!$J$30,NA())) -> 0 | I18: =H18*IF(AND(ISNUMBER(Допущения!$K$30),Допущения!$K$30>=0,Допущения!$K$30<=1),Допущения!$K$30,NA()) -> 0 | J18: =IF(C18=0,0,IF(IF(AND(ISNUMBER(Допущения!$L$30),Допущения!$L$30>=0,Допущения!$L$30<=1),Допущения!$L$30,NA())*Допущения!$B$24<=1,I18*IF(AND(ISNUMBER(Допущения!$L$30),Допущения!$L$30>=0,Допущения!$L$30<=1),Допущения!$L$30,NA())*Допущения!$B$24,NA())) -> 0 | K18: =IF(5<=IF(AND(ISNUMBER(Допущения!$B$17),Допущения!$B$17>=0,Допущения!$B$17=INT(Допущения!$B$17),Допущения!$B$17<=12),Допущения!$B$17,NA()),0,INDEX($J$6:$J$41,(5-IF(AND(ISNUMBER(Допущения!$B$17),Допущения!$B$17>=0,Допущения!$B$17=INT(Допущения!$B$17),Допущения!$B$17<=12),Допущения!$B$17,NA())-1)*3+1)) -> 0 | L18: =G18+K18 -> 40 | M18: =I18*IF(AND(ISNUMBER(Допущения!$M$30),Допущения!$M$30>=0),Допущения!$M$30,NA()) -> 0 | N18: =M18*IF(AND(ISNUMBER(Допущения!$B$7),Допущения!$B$7>=0),Допущения!$B$7,NA()) -> 0
A19: Месяц 5 | B19: =Допущения!$A$31 -> Команда | C19: =Допущения!$N$31 -> 0 | D19: =IF(AND(COUNT(Допущения!$C$30:$C$32)=3,MIN(Допущения!$C$30:$C$32)>=0,MAX(Допущения!$C$30:$C$32)<=1,ABS(SUM(Допущения!$C$30:$C$32)-1)<0.00000001),IF(AND(ISNUMBER(Допущения!$B$44),Допущения!$B$44>=0),Допущения!$B$44,NA())*Допущения!$C$31,NA()) -> 70000 | E19: =IF(AND(ISNUMBER(Допущения!$H$31),Допущения!$H$31>0),Допущения!$H$31,NA())*Допущения!$B$23 -> 70 | F19: =D19/E19 -> 1000 | G19: =IF(C19=1,0,IF(IF(AND(ISNUMBER(Допущения!$I$31),Допущения!$I$31>=0,Допущения!$I$31<=1),Допущения!$I$31,NA())*Допущения!$B$24<=1,F19*IF(AND(ISNUMBER(Допущения!$I$31),Допущения!$I$31>=0,Допущения!$I$31<=1),Допущения!$I$31,NA())*Допущения!$B$24,NA())) -> 9 | H19: =IF(C19=0,0,F19*IF(AND(ISNUMBER(Допущения!$J$31),Допущения!$J$31>=0,Допущения!$J$31<=1),Допущения!$J$31,NA())) -> 0 | I19: =H19*IF(AND(ISNUMBER(Допущения!$K$31),Допущения!$K$31>=0,Допущения!$K$31<=1),Допущения!$K$31,NA()) -> 0 | J19: =IF(C19=0,0,IF(IF(AND(ISNUMBER(Допущения!$L$31),Допущения!$L$31>=0,Допущения!$L$31<=1),Допущения!$L$31,NA())*Допущения!$B$24<=1,I19*IF(AND(ISNUMBER(Допущения!$L$31),Допущения!$L$31>=0,Допущения!$L$31<=1),Допущения!$L$31,NA())*Допущения!$B$24,NA())) -> 0 | K19: =IF(5<=IF(AND(ISNUMBER(Допущения!$B$17),Допущения!$B$17>=0,Допущения!$B$17=INT(Допущения!$B$17),Допущения!$B$17<=12),Допущения!$B$17,NA()),0,INDEX($J$6:$J$41,(5-IF(AND(ISNUMBER(Допущения!$B$17),Допущения!$B$17>=0,Допущения!$B$17=INT(Допущения!$B$17),Допущения!$B$17<=12),Допущения!$B$17,NA())-1)*3+2)) -> 0 | L19: =G19+K19 -> 9 | M19: =I19*IF(AND(ISNUMBER(Допущения!$M$31),Допущения!$M$31>=0),Допущения!$M$31,NA()) -> 0 | N19: =M19*IF(AND(ISNUMBER(Допущения!$B$7),Допущения!$B$7>=0),Допущения!$B$7,NA()) -> 0
A20: Месяц 5 | B20: =Допущения!$A$32 -> Бизнес | C20: =Допущения!$N$32 -> 1 | D20: =IF(AND(COUNT(Допущения!$C$30:$C$32)=3,MIN(Допущения!$C$30:$C$32)>=0,MAX(Допущения!$C$30:$C$32)<=1,ABS(SUM(Допущения!$C$30:$C$32)-1)<0.00000001),IF(AND(ISNUMBER(Допущения!$B$44),Допущения!$B$44>=0),Допущения!$B$44,NA())*Допущения!$C$32,NA()) -> 30000 | E20: =IF(AND(ISNUMBER(Допущения!$H$32),Допущения!$H$32>0),Допущения!$H$32,NA())*Допущения!$B$23 -> 120 | F20: =D20/E20 -> 250 | G20: =IF(C20=1,0,IF(IF(AND(ISNUMBER(Допущения!$I$32),Допущения!$I$32>=0,Допущения!$I$32<=1),Допущения!$I$32,NA())*Допущения!$B$24<=1,F20*IF(AND(ISNUMBER(Допущения!$I$32),Допущения!$I$32>=0,Допущения!$I$32<=1),Допущения!$I$32,NA())*Допущения!$B$24,NA())) -> 0 | H20: =IF(C20=0,0,F20*IF(AND(ISNUMBER(Допущения!$J$32),Допущения!$J$32>=0,Допущения!$J$32<=1),Допущения!$J$32,NA())) -> 10 | I20: =H20*IF(AND(ISNUMBER(Допущения!$K$32),Допущения!$K$32>=0,Допущения!$K$32<=1),Допущения!$K$32,NA()) -> 8 | J20: =IF(C20=0,0,IF(IF(AND(ISNUMBER(Допущения!$L$32),Допущения!$L$32>=0,Допущения!$L$32<=1),Допущения!$L$32,NA())*Допущения!$B$24<=1,I20*IF(AND(ISNUMBER(Допущения!$L$32),Допущения!$L$32>=0,Допущения!$L$32<=1),Допущения!$L$32,NA())*Допущения!$B$24,NA())) -> 2.4 | K20: =IF(5<=IF(AND(ISNUMBER(Допущения!$B$17),Допущения!$B$17>=0,Допущения!$B$17=INT(Допущения!$B$17),Допущения!$B$17<=12),Допущения!$B$17,NA()),0,INDEX($J$6:$J$41,(5-IF(AND(ISNUMBER(Допущения!$B$17),Допущения!$B$17>=0,Допущения!$B$17=INT(Допущения!$B$17),Допущения!$B$17<=12),Допущения!$B$17,NA())-1)*3+3)) -> 2.4 | L20: =G20+K20 -> 2.4 | M20: =I20*IF(AND(ISNUMBER(Допущения!$M$32),Допущения!$M$32>=0),Допущения!$M$32,NA()) -> 12 | N20: =M20*IF(AND(ISNUMBER(Допущения!$B$7),Допущения!$B$7>=0),Допущения!$B$7,NA()) -> 12000
A21: Месяц 6 | B21: =Допущения!$A$30 -> Старт | C21: =Допущения!$N$30 -> 0 | D21: =IF(AND(COUNT(Допущения!$C$30:$C$32)=3,MIN(Допущения!$C$30:$C$32)>=0,MAX(Допущения!$C$30:$C$32)<=1,ABS(SUM(Допущения!$C$30:$C$32)-1)<0.00000001),IF(AND(ISNUMBER(Допущения!$B$45),Допущения!$B$45>=0),Допущения!$B$45,NA())*Допущения!$C$30,NA()) -> 100000 | E21: =IF(AND(ISNUMBER(Допущения!$H$30),Допущения!$H$30>0),Допущения!$H$30,NA())*Допущения!$B$23 -> 45 | F21: =D21/E21 -> 2222.2222 | G21: =IF(C21=1,0,IF(IF(AND(ISNUMBER(Допущения!$I$30),Допущения!$I$30>=0,Допущения!$I$30<=1),Допущения!$I$30,NA())*Допущения!$B$24<=1,F21*IF(AND(ISNUMBER(Допущения!$I$30),Допущения!$I$30>=0,Допущения!$I$30<=1),Допущения!$I$30,NA())*Допущения!$B$24,NA())) -> 40 | H21: =IF(C21=0,0,F21*IF(AND(ISNUMBER(Допущения!$J$30),Допущения!$J$30>=0,Допущения!$J$30<=1),Допущения!$J$30,NA())) -> 0 | I21: =H21*IF(AND(ISNUMBER(Допущения!$K$30),Допущения!$K$30>=0,Допущения!$K$30<=1),Допущения!$K$30,NA()) -> 0 | J21: =IF(C21=0,0,IF(IF(AND(ISNUMBER(Допущения!$L$30),Допущения!$L$30>=0,Допущения!$L$30<=1),Допущения!$L$30,NA())*Допущения!$B$24<=1,I21*IF(AND(ISNUMBER(Допущения!$L$30),Допущения!$L$30>=0,Допущения!$L$30<=1),Допущения!$L$30,NA())*Допущения!$B$24,NA())) -> 0 | K21: =IF(6<=IF(AND(ISNUMBER(Допущения!$B$17),Допущения!$B$17>=0,Допущения!$B$17=INT(Допущения!$B$17),Допущения!$B$17<=12),Допущения!$B$17,NA()),0,INDEX($J$6:$J$41,(6-IF(AND(ISNUMBER(Допущения!$B$17),Допущения!$B$17>=0,Допущения!$B$17=INT(Допущения!$B$17),Допущения!$B$17<=12),Допущения!$B$17,NA())-1)*3+1)) -> 0 | L21: =G21+K21 -> 40 | M21: =I21*IF(AND(ISNUMBER(Допущения!$M$30),Допущения!$M$30>=0),Допущения!$M$30,NA()) -> 0 | N21: =M21*IF(AND(ISNUMBER(Допущения!$B$7),Допущения!$B$7>=0),Допущения!$B$7,NA()) -> 0
A22: Месяц 6 | B22: =Допущения!$A$31 -> Команда | C22: =Допущения!$N$31 -> 0 | D22: =IF(AND(COUNT(Допущения!$C$30:$C$32)=3,MIN(Допущения!$C$30:$C$32)>=0,MAX(Допущения!$C$30:$C$32)<=1,ABS(SUM(Допущения!$C$30:$C$32)-1)<0.00000001),IF(AND(ISNUMBER(Допущения!$B$45),Допущения!$B$45>=0),Допущения!$B$45,NA())*Допущения!$C$31,NA()) -> 70000 | E22: =IF(AND(ISNUMBER(Допущения!$H$31),Допущения!$H$31>0),Допущения!$H$31,NA())*Допущения!$B$23 -> 70 | F22: =D22/E22 -> 1000 | G22: =IF(C22=1,0,IF(IF(AND(ISNUMBER(Допущения!$I$31),Допущения!$I$31>=0,Допущения!$I$31<=1),Допущения!$I$31,NA())*Допущения!$B$24<=1,F22*IF(AND(ISNUMBER(Допущения!$I$31),Допущения!$I$31>=0,Допущения!$I$31<=1),Допущения!$I$31,NA())*Допущения!$B$24,NA())) -> 9 | H22: =IF(C22=0,0,F22*IF(AND(ISNUMBER(Допущения!$J$31),Допущения!$J$31>=0,Допущения!$J$31<=1),Допущения!$J$31,NA())) -> 0 | I22: =H22*IF(AND(ISNUMBER(Допущения!$K$31),Допущения!$K$31>=0,Допущения!$K$31<=1),Допущения!$K$31,NA()) -> 0 | J22: =IF(C22=0,0,IF(IF(AND(ISNUMBER(Допущения!$L$31),Допущения!$L$31>=0,Допущения!$L$31<=1),Допущения!$L$31,NA())*Допущения!$B$24<=1,I22*IF(AND(ISNUMBER(Допущения!$L$31),Допущения!$L$31>=0,Допущения!$L$31<=1),Допущения!$L$31,NA())*Допущения!$B$24,NA())) -> 0 | K22: =IF(6<=IF(AND(ISNUMBER(Допущения!$B$17),Допущения!$B$17>=0,Допущения!$B$17=INT(Допущения!$B$17),Допущения!$B$17<=12),Допущения!$B$17,NA()),0,INDEX($J$6:$J$41,(6-IF(AND(ISNUMBER(Допущения!$B$17),Допущения!$B$17>=0,Допущения!$B$17=INT(Допущения!$B$17),Допущения!$B$17<=12),Допущения!$B$17,NA())-1)*3+2)) -> 0 | L22: =G22+K22 -> 9 | M22: =I22*IF(AND(ISNUMBER(Допущения!$M$31),Допущения!$M$31>=0),Допущения!$M$31,NA()) -> 0 | N22: =M22*IF(AND(ISNUMBER(Допущения!$B$7),Допущения!$B$7>=0),Допущения!$B$7,NA()) -> 0
A23: Месяц 6 | B23: =Допущения!$A$32 -> Бизнес | C23: =Допущения!$N$32 -> 1 | D23: =IF(AND(COUNT(Допущения!$C$30:$C$32)=3,MIN(Допущения!$C$30:$C$32)>=0,MAX(Допущения!$C$30:$C$32)<=1,ABS(SUM(Допущения!$C$30:$C$32)-1)<0.00000001),IF(AND(ISNUMBER(Допущения!$B$45),Допущения!$B$45>=0),Допущения!$B$45,NA())*Допущения!$C$32,NA()) -> 30000 | E23: =IF(AND(ISNUMBER(Допущения!$H$32),Допущения!$H$32>0),Допущения!$H$32,NA())*Допущения!$B$23 -> 120 | F23: =D23/E23 -> 250 | G23: =IF(C23=1,0,IF(IF(AND(ISNUMBER(Допущения!$I$32),Допущения!$I$32>=0,Допущения!$I$32<=1),Допущения!$I$32,NA())*Допущения!$B$24<=1,F23*IF(AND(ISNUMBER(Допущения!$I$32),Допущения!$I$32>=0,Допущения!$I$32<=1),Допущения!$I$32,NA())*Допущения!$B$24,NA())) -> 0 | H23: =IF(C23=0,0,F23*IF(AND(ISNUMBER(Допущения!$J$32),Допущения!$J$32>=0,Допущения!$J$32<=1),Допущения!$J$32,NA())) -> 10 | I23: =H23*IF(AND(ISNUMBER(Допущения!$K$32),Допущения!$K$32>=0,Допущения!$K$32<=1),Допущения!$K$32,NA()) -> 8 | J23: =IF(C23=0,0,IF(IF(AND(ISNUMBER(Допущения!$L$32),Допущения!$L$32>=0,Допущения!$L$32<=1),Допущения!$L$32,NA())*Допущения!$B$24<=1,I23*IF(AND(ISNUMBER(Допущения!$L$32),Допущения!$L$32>=0,Допущения!$L$32<=1),Допущения!$L$32,NA())*Допущения!$B$24,NA())) -> 2.4 | K23: =IF(6<=IF(AND(ISNUMBER(Допущения!$B$17),Допущения!$B$17>=0,Допущения!$B$17=INT(Допущения!$B$17),Допущения!$B$17<=12),Допущения!$B$17,NA()),0,INDEX($J$6:$J$41,(6-IF(AND(ISNUMBER(Допущения!$B$17),Допущения!$B$17>=0,Допущения!$B$17=INT(Допущения!$B$17),Допущения!$B$17<=12),Допущения!$B$17,NA())-1)*3+3)) -> 2.4 | L23: =G23+K23 -> 2.4 | M23: =I23*IF(AND(ISNUMBER(Допущения!$M$32),Допущения!$M$32>=0),Допущения!$M$32,NA()) -> 12 | N23: =M23*IF(AND(ISNUMBER(Допущения!$B$7),Допущения!$B$7>=0),Допущения!$B$7,NA()) -> 12000
A24: Месяц 7 | B24: =Допущения!$A$30 -> Старт | C24: =Допущения!$N$30 -> 0 | D24: =IF(AND(COUNT(Допущения!$C$30:$C$32)=3,MIN(Допущения!$C$30:$C$32)>=0,MAX(Допущения!$C$30:$C$32)<=1,ABS(SUM(Допущения!$C$30:$C$32)-1)<0.00000001),IF(AND(ISNUMBER(Допущения!$B$46),Допущения!$B$46>=0),Допущения!$B$46,NA())*Допущения!$C$30,NA()) -> 100000 | E24: =IF(AND(ISNUMBER(Допущения!$H$30),Допущения!$H$30>0),Допущения!$H$30,NA())*Допущения!$B$23 -> 45 | F24: =D24/E24 -> 2222.2222 | G24: =IF(C24=1,0,IF(IF(AND(ISNUMBER(Допущения!$I$30),Допущения!$I$30>=0,Допущения!$I$30<=1),Допущения!$I$30,NA())*Допущения!$B$24<=1,F24*IF(AND(ISNUMBER(Допущения!$I$30),Допущения!$I$30>=0,Допущения!$I$30<=1),Допущения!$I$30,NA())*Допущения!$B$24,NA())) -> 40 | H24: =IF(C24=0,0,F24*IF(AND(ISNUMBER(Допущения!$J$30),Допущения!$J$30>=0,Допущения!$J$30<=1),Допущения!$J$30,NA())) -> 0 | I24: =H24*IF(AND(ISNUMBER(Допущения!$K$30),Допущения!$K$30>=0,Допущения!$K$30<=1),Допущения!$K$30,NA()) -> 0 | J24: =IF(C24=0,0,IF(IF(AND(ISNUMBER(Допущения!$L$30),Допущения!$L$30>=0,Допущения!$L$30<=1),Допущения!$L$30,NA())*Допущения!$B$24<=1,I24*IF(AND(ISNUMBER(Допущения!$L$30),Допущения!$L$30>=0,Допущения!$L$30<=1),Допущения!$L$30,NA())*Допущения!$B$24,NA())) -> 0 | K24: =IF(7<=IF(AND(ISNUMBER(Допущения!$B$17),Допущения!$B$17>=0,Допущения!$B$17=INT(Допущения!$B$17),Допущения!$B$17<=12),Допущения!$B$17,NA()),0,INDEX($J$6:$J$41,(7-IF(AND(ISNUMBER(Допущения!$B$17),Допущения!$B$17>=0,Допущения!$B$17=INT(Допущения!$B$17),Допущения!$B$17<=12),Допущения!$B$17,NA())-1)*3+1)) -> 0 | L24: =G24+K24 -> 40 | M24: =I24*IF(AND(ISNUMBER(Допущения!$M$30),Допущения!$M$30>=0),Допущения!$M$30,NA()) -> 0 | N24: =M24*IF(AND(ISNUMBER(Допущения!$B$7),Допущения!$B$7>=0),Допущения!$B$7,NA()) -> 0
A25: Месяц 7 | B25: =Допущения!$A$31 -> Команда | C25: =Допущения!$N$31 -> 0 | D25: =IF(AND(COUNT(Допущения!$C$30:$C$32)=3,MIN(Допущения!$C$30:$C$32)>=0,MAX(Допущения!$C$30:$C$32)<=1,ABS(SUM(Допущения!$C$30:$C$32)-1)<0.00000001),IF(AND(ISNUMBER(Допущения!$B$46),Допущения!$B$46>=0),Допущения!$B$46,NA())*Допущения!$C$31,NA()) -> 70000 | E25: =IF(AND(ISNUMBER(Допущения!$H$31),Допущения!$H$31>0),Допущения!$H$31,NA())*Допущения!$B$23 -> 70 | F25: =D25/E25 -> 1000 | G25: =IF(C25=1,0,IF(IF(AND(ISNUMBER(Допущения!$I$31),Допущения!$I$31>=0,Допущения!$I$31<=1),Допущения!$I$31,NA())*Допущения!$B$24<=1,F25*IF(AND(ISNUMBER(Допущения!$I$31),Допущения!$I$31>=0,Допущения!$I$31<=1),Допущения!$I$31,NA())*Допущения!$B$24,NA())) -> 9 | H25: =IF(C25=0,0,F25*IF(AND(ISNUMBER(Допущения!$J$31),Допущения!$J$31>=0,Допущения!$J$31<=1),Допущения!$J$31,NA())) -> 0 | I25: =H25*IF(AND(ISNUMBER(Допущения!$K$31),Допущения!$K$31>=0,Допущения!$K$31<=1),Допущения!$K$31,NA()) -> 0 | J25: =IF(C25=0,0,IF(IF(AND(ISNUMBER(Допущения!$L$31),Допущения!$L$31>=0,Допущения!$L$31<=1),Допущения!$L$31,NA())*Допущения!$B$24<=1,I25*IF(AND(ISNUMBER(Допущения!$L$31),Допущения!$L$31>=0,Допущения!$L$31<=1),Допущения!$L$31,NA())*Допущения!$B$24,NA())) -> 0 | K25: =IF(7<=IF(AND(ISNUMBER(Допущения!$B$17),Допущения!$B$17>=0,Допущения!$B$17=INT(Допущения!$B$17),Допущения!$B$17<=12),Допущения!$B$17,NA()),0,INDEX($J$6:$J$41,(7-IF(AND(ISNUMBER(Допущения!$B$17),Допущения!$B$17>=0,Допущения!$B$17=INT(Допущения!$B$17),Допущения!$B$17<=12),Допущения!$B$17,NA())-1)*3+2)) -> 0 | L25: =G25+K25 -> 9 | M25: =I25*IF(AND(ISNUMBER(Допущения!$M$31),Допущения!$M$31>=0),Допущения!$M$31,NA()) -> 0 | N25: =M25*IF(AND(ISNUMBER(Допущения!$B$7),Допущения!$B$7>=0),Допущения!$B$7,NA()) -> 0
A26: Месяц 7 | B26: =Допущения!$A$32 -> Бизнес | C26: =Допущения!$N$32 -> 1 | D26: =IF(AND(COUNT(Допущения!$C$30:$C$32)=3,MIN(Допущения!$C$30:$C$32)>=0,MAX(Допущения!$C$30:$C$32)<=1,ABS(SUM(Допущения!$C$30:$C$32)-1)<0.00000001),IF(AND(ISNUMBER(Допущения!$B$46),Допущения!$B$46>=0),Допущения!$B$46,NA())*Допущения!$C$32,NA()) -> 30000 | E26: =IF(AND(ISNUMBER(Допущения!$H$32),Допущения!$H$32>0),Допущения!$H$32,NA())*Допущения!$B$23 -> 120 | F26: =D26/E26 -> 250 | G26: =IF(C26=1,0,IF(IF(AND(ISNUMBER(Допущения!$I$32),Допущения!$I$32>=0,Допущения!$I$32<=1),Допущения!$I$32,NA())*Допущения!$B$24<=1,F26*IF(AND(ISNUMBER(Допущения!$I$32),Допущения!$I$32>=0,Допущения!$I$32<=1),Допущения!$I$32,NA())*Допущения!$B$24,NA())) -> 0 | H26: =IF(C26=0,0,F26*IF(AND(ISNUMBER(Допущения!$J$32),Допущения!$J$32>=0,Допущения!$J$32<=1),Допущения!$J$32,NA())) -> 10 | I26: =H26*IF(AND(ISNUMBER(Допущения!$K$32),Допущения!$K$32>=0,Допущения!$K$32<=1),Допущения!$K$32,NA()) -> 8 | J26: =IF(C26=0,0,IF(IF(AND(ISNUMBER(Допущения!$L$32),Допущения!$L$32>=0,Допущения!$L$32<=1),Допущения!$L$32,NA())*Допущения!$B$24<=1,I26*IF(AND(ISNUMBER(Допущения!$L$32),Допущения!$L$32>=0,Допущения!$L$32<=1),Допущения!$L$32,NA())*Допущения!$B$24,NA())) -> 2.4 | K26: =IF(7<=IF(AND(ISNUMBER(Допущения!$B$17),Допущения!$B$17>=0,Допущения!$B$17=INT(Допущения!$B$17),Допущения!$B$17<=12),Допущения!$B$17,NA()),0,INDEX($J$6:$J$41,(7-IF(AND(ISNUMBER(Допущения!$B$17),Допущения!$B$17>=0,Допущения!$B$17=INT(Допущения!$B$17),Допущения!$B$17<=12),Допущения!$B$17,NA())-1)*3+3)) -> 2.4 | L26: =G26+K26 -> 2.4 | M26: =I26*IF(AND(ISNUMBER(Допущения!$M$32),Допущения!$M$32>=0),Допущения!$M$32,NA()) -> 12 | N26: =M26*IF(AND(ISNUMBER(Допущения!$B$7),Допущения!$B$7>=0),Допущения!$B$7,NA()) -> 12000
A27: Месяц 8 | B27: =Допущения!$A$30 -> Старт | C27: =Допущения!$N$30 -> 0 | D27: =IF(AND(COUNT(Допущения!$C$30:$C$32)=3,MIN(Допущения!$C$30:$C$32)>=0,MAX(Допущения!$C$30:$C$32)<=1,ABS(SUM(Допущения!$C$30:$C$32)-1)<0.00000001),IF(AND(ISNUMBER(Допущения!$B$47),Допущения!$B$47>=0),Допущения!$B$47,NA())*Допущения!$C$30,NA()) -> 100000 | E27: =IF(AND(ISNUMBER(Допущения!$H$30),Допущения!$H$30>0),Допущения!$H$30,NA())*Допущения!$B$23 -> 45 | F27: =D27/E27 -> 2222.2222 | G27: =IF(C27=1,0,IF(IF(AND(ISNUMBER(Допущения!$I$30),Допущения!$I$30>=0,Допущения!$I$30<=1),Допущения!$I$30,NA())*Допущения!$B$24<=1,F27*IF(AND(ISNUMBER(Допущения!$I$30),Допущения!$I$30>=0,Допущения!$I$30<=1),Допущения!$I$30,NA())*Допущения!$B$24,NA())) -> 40 | H27: =IF(C27=0,0,F27*IF(AND(ISNUMBER(Допущения!$J$30),Допущения!$J$30>=0,Допущения!$J$30<=1),Допущения!$J$30,NA())) -> 0 | I27: =H27*IF(AND(ISNUMBER(Допущения!$K$30),Допущения!$K$30>=0,Допущения!$K$30<=1),Допущения!$K$30,NA()) -> 0 | J27: =IF(C27=0,0,IF(IF(AND(ISNUMBER(Допущения!$L$30),Допущения!$L$30>=0,Допущения!$L$30<=1),Допущения!$L$30,NA())*Допущения!$B$24<=1,I27*IF(AND(ISNUMBER(Допущения!$L$30),Допущения!$L$30>=0,Допущения!$L$30<=1),Допущения!$L$30,NA())*Допущения!$B$24,NA())) -> 0 | K27: =IF(8<=IF(AND(ISNUMBER(Допущения!$B$17),Допущения!$B$17>=0,Допущения!$B$17=INT(Допущения!$B$17),Допущения!$B$17<=12),Допущения!$B$17,NA()),0,INDEX($J$6:$J$41,(8-IF(AND(ISNUMBER(Допущения!$B$17),Допущения!$B$17>=0,Допущения!$B$17=INT(Допущения!$B$17),Допущения!$B$17<=12),Допущения!$B$17,NA())-1)*3+1)) -> 0 | L27: =G27+K27 -> 40 | M27: =I27*IF(AND(ISNUMBER(Допущения!$M$30),Допущения!$M$30>=0),Допущения!$M$30,NA()) -> 0 | N27: =M27*IF(AND(ISNUMBER(Допущения!$B$7),Допущения!$B$7>=0),Допущения!$B$7,NA()) -> 0
A28: Месяц 8 | B28: =Допущения!$A$31 -> Команда | C28: =Допущения!$N$31 -> 0 | D28: =IF(AND(COUNT(Допущения!$C$30:$C$32)=3,MIN(Допущения!$C$30:$C$32)>=0,MAX(Допущения!$C$30:$C$32)<=1,ABS(SUM(Допущения!$C$30:$C$32)-1)<0.00000001),IF(AND(ISNUMBER(Допущения!$B$47),Допущения!$B$47>=0),Допущения!$B$47,NA())*Допущения!$C$31,NA()) -> 70000 | E28: =IF(AND(ISNUMBER(Допущения!$H$31),Допущения!$H$31>0),Допущения!$H$31,NA())*Допущения!$B$23 -> 70 | F28: =D28/E28 -> 1000 | G28: =IF(C28=1,0,IF(IF(AND(ISNUMBER(Допущения!$I$31),Допущения!$I$31>=0,Допущения!$I$31<=1),Допущения!$I$31,NA())*Допущения!$B$24<=1,F28*IF(AND(ISNUMBER(Допущения!$I$31),Допущения!$I$31>=0,Допущения!$I$31<=1),Допущения!$I$31,NA())*Допущения!$B$24,NA())) -> 9 | H28: =IF(C28=0,0,F28*IF(AND(ISNUMBER(Допущения!$J$31),Допущения!$J$31>=0,Допущения!$J$31<=1),Допущения!$J$31,NA())) -> 0 | I28: =H28*IF(AND(ISNUMBER(Допущения!$K$31),Допущения!$K$31>=0,Допущения!$K$31<=1),Допущения!$K$31,NA()) -> 0 | J28: =IF(C28=0,0,IF(IF(AND(ISNUMBER(Допущения!$L$31),Допущения!$L$31>=0,Допущения!$L$31<=1),Допущения!$L$31,NA())*Допущения!$B$24<=1,I28*IF(AND(ISNUMBER(Допущения!$L$31),Допущения!$L$31>=0,Допущения!$L$31<=1),Допущения!$L$31,NA())*Допущения!$B$24,NA())) -> 0 | K28: =IF(8<=IF(AND(ISNUMBER(Допущения!$B$17),Допущения!$B$17>=0,Допущения!$B$17=INT(Допущения!$B$17),Допущения!$B$17<=12),Допущения!$B$17,NA()),0,INDEX($J$6:$J$41,(8-IF(AND(ISNUMBER(Допущения!$B$17),Допущения!$B$17>=0,Допущения!$B$17=INT(Допущения!$B$17),Допущения!$B$17<=12),Допущения!$B$17,NA())-1)*3+2)) -> 0 | L28: =G28+K28 -> 9 | M28: =I28*IF(AND(ISNUMBER(Допущения!$M$31),Допущения!$M$31>=0),Допущения!$M$31,NA()) -> 0 | N28: =M28*IF(AND(ISNUMBER(Допущения!$B$7),Допущения!$B$7>=0),Допущения!$B$7,NA()) -> 0
A29: Месяц 8 | B29: =Допущения!$A$32 -> Бизнес | C29: =Допущения!$N$32 -> 1 | D29: =IF(AND(COUNT(Допущения!$C$30:$C$32)=3,MIN(Допущения!$C$30:$C$32)>=0,MAX(Допущения!$C$30:$C$32)<=1,ABS(SUM(Допущения!$C$30:$C$32)-1)<0.00000001),IF(AND(ISNUMBER(Допущения!$B$47),Допущения!$B$47>=0),Допущения!$B$47,NA())*Допущения!$C$32,NA()) -> 30000 | E29: =IF(AND(ISNUMBER(Допущения!$H$32),Допущения!$H$32>0),Допущения!$H$32,NA())*Допущения!$B$23 -> 120 | F29: =D29/E29 -> 250 | G29: =IF(C29=1,0,IF(IF(AND(ISNUMBER(Допущения!$I$32),Допущения!$I$32>=0,Допущения!$I$32<=1),Допущения!$I$32,NA())*Допущения!$B$24<=1,F29*IF(AND(ISNUMBER(Допущения!$I$32),Допущения!$I$32>=0,Допущения!$I$32<=1),Допущения!$I$32,NA())*Допущения!$B$24,NA())) -> 0 | H29: =IF(C29=0,0,F29*IF(AND(ISNUMBER(Допущения!$J$32),Допущения!$J$32>=0,Допущения!$J$32<=1),Допущения!$J$32,NA())) -> 10 | I29: =H29*IF(AND(ISNUMBER(Допущения!$K$32),Допущения!$K$32>=0,Допущения!$K$32<=1),Допущения!$K$32,NA()) -> 8 | J29: =IF(C29=0,0,IF(IF(AND(ISNUMBER(Допущения!$L$32),Допущения!$L$32>=0,Допущения!$L$32<=1),Допущения!$L$32,NA())*Допущения!$B$24<=1,I29*IF(AND(ISNUMBER(Допущения!$L$32),Допущения!$L$32>=0,Допущения!$L$32<=1),Допущения!$L$32,NA())*Допущения!$B$24,NA())) -> 2.4 | K29: =IF(8<=IF(AND(ISNUMBER(Допущения!$B$17),Допущения!$B$17>=0,Допущения!$B$17=INT(Допущения!$B$17),Допущения!$B$17<=12),Допущения!$B$17,NA()),0,INDEX($J$6:$J$41,(8-IF(AND(ISNUMBER(Допущения!$B$17),Допущения!$B$17>=0,Допущения!$B$17=INT(Допущения!$B$17),Допущения!$B$17<=12),Допущения!$B$17,NA())-1)*3+3)) -> 2.4 | L29: =G29+K29 -> 2.4 | M29: =I29*IF(AND(ISNUMBER(Допущения!$M$32),Допущения!$M$32>=0),Допущения!$M$32,NA()) -> 12 | N29: =M29*IF(AND(ISNUMBER(Допущения!$B$7),Допущения!$B$7>=0),Допущения!$B$7,NA()) -> 12000
A30: Месяц 9 | B30: =Допущения!$A$30 -> Старт | C30: =Допущения!$N$30 -> 0 | D30: =IF(AND(COUNT(Допущения!$C$30:$C$32)=3,MIN(Допущения!$C$30:$C$32)>=0,MAX(Допущения!$C$30:$C$32)<=1,ABS(SUM(Допущения!$C$30:$C$32)-1)<0.00000001),IF(AND(ISNUMBER(Допущения!$B$48),Допущения!$B$48>=0),Допущения!$B$48,NA())*Допущения!$C$30,NA()) -> 100000 | E30: =IF(AND(ISNUMBER(Допущения!$H$30),Допущения!$H$30>0),Допущения!$H$30,NA())*Допущения!$B$23 -> 45 | F30: =D30/E30 -> 2222.2222 | G30: =IF(C30=1,0,IF(IF(AND(ISNUMBER(Допущения!$I$30),Допущения!$I$30>=0,Допущения!$I$30<=1),Допущения!$I$30,NA())*Допущения!$B$24<=1,F30*IF(AND(ISNUMBER(Допущения!$I$30),Допущения!$I$30>=0,Допущения!$I$30<=1),Допущения!$I$30,NA())*Допущения!$B$24,NA())) -> 40 | H30: =IF(C30=0,0,F30*IF(AND(ISNUMBER(Допущения!$J$30),Допущения!$J$30>=0,Допущения!$J$30<=1),Допущения!$J$30,NA())) -> 0 | I30: =H30*IF(AND(ISNUMBER(Допущения!$K$30),Допущения!$K$30>=0,Допущения!$K$30<=1),Допущения!$K$30,NA()) -> 0 | J30: =IF(C30=0,0,IF(IF(AND(ISNUMBER(Допущения!$L$30),Допущения!$L$30>=0,Допущения!$L$30<=1),Допущения!$L$30,NA())*Допущения!$B$24<=1,I30*IF(AND(ISNUMBER(Допущения!$L$30),Допущения!$L$30>=0,Допущения!$L$30<=1),Допущения!$L$30,NA())*Допущения!$B$24,NA())) -> 0 | K30: =IF(9<=IF(AND(ISNUMBER(Допущения!$B$17),Допущения!$B$17>=0,Допущения!$B$17=INT(Допущения!$B$17),Допущения!$B$17<=12),Допущения!$B$17,NA()),0,INDEX($J$6:$J$41,(9-IF(AND(ISNUMBER(Допущения!$B$17),Допущения!$B$17>=0,Допущения!$B$17=INT(Допущения!$B$17),Допущения!$B$17<=12),Допущения!$B$17,NA())-1)*3+1)) -> 0 | L30: =G30+K30 -> 40 | M30: =I30*IF(AND(ISNUMBER(Допущения!$M$30),Допущения!$M$30>=0),Допущения!$M$30,NA()) -> 0 | N30: =M30*IF(AND(ISNUMBER(Допущения!$B$7),Допущения!$B$7>=0),Допущения!$B$7,NA()) -> 0
A31: Месяц 9 | B31: =Допущения!$A$31 -> Команда | C31: =Допущения!$N$31 -> 0 | D31: =IF(AND(COUNT(Допущения!$C$30:$C$32)=3,MIN(Допущения!$C$30:$C$32)>=0,MAX(Допущения!$C$30:$C$32)<=1,ABS(SUM(Допущения!$C$30:$C$32)-1)<0.00000001),IF(AND(ISNUMBER(Допущения!$B$48),Допущения!$B$48>=0),Допущения!$B$48,NA())*Допущения!$C$31,NA()) -> 70000 | E31: =IF(AND(ISNUMBER(Допущения!$H$31),Допущения!$H$31>0),Допущения!$H$31,NA())*Допущения!$B$23 -> 70 | F31: =D31/E31 -> 1000 | G31: =IF(C31=1,0,IF(IF(AND(ISNUMBER(Допущения!$I$31),Допущения!$I$31>=0,Допущения!$I$31<=1),Допущения!$I$31,NA())*Допущения!$B$24<=1,F31*IF(AND(ISNUMBER(Допущения!$I$31),Допущения!$I$31>=0,Допущения!$I$31<=1),Допущения!$I$31,NA())*Допущения!$B$24,NA())) -> 9 | H31: =IF(C31=0,0,F31*IF(AND(ISNUMBER(Допущения!$J$31),Допущения!$J$31>=0,Допущения!$J$31<=1),Допущения!$J$31,NA())) -> 0 | I31: =H31*IF(AND(ISNUMBER(Допущения!$K$31),Допущения!$K$31>=0,Допущения!$K$31<=1),Допущения!$K$31,NA()) -> 0 | J31: =IF(C31=0,0,IF(IF(AND(ISNUMBER(Допущения!$L$31),Допущения!$L$31>=0,Допущения!$L$31<=1),Допущения!$L$31,NA())*Допущения!$B$24<=1,I31*IF(AND(ISNUMBER(Допущения!$L$31),Допущения!$L$31>=0,Допущения!$L$31<=1),Допущения!$L$31,NA())*Допущения!$B$24,NA())) -> 0 | K31: =IF(9<=IF(AND(ISNUMBER(Допущения!$B$17),Допущения!$B$17>=0,Допущения!$B$17=INT(Допущения!$B$17),Допущения!$B$17<=12),Допущения!$B$17,NA()),0,INDEX($J$6:$J$41,(9-IF(AND(ISNUMBER(Допущения!$B$17),Допущения!$B$17>=0,Допущения!$B$17=INT(Допущения!$B$17),Допущения!$B$17<=12),Допущения!$B$17,NA())-1)*3+2)) -> 0 | L31: =G31+K31 -> 9 | M31: =I31*IF(AND(ISNUMBER(Допущения!$M$31),Допущения!$M$31>=0),Допущения!$M$31,NA()) -> 0 | N31: =M31*IF(AND(ISNUMBER(Допущения!$B$7),Допущения!$B$7>=0),Допущения!$B$7,NA()) -> 0
