Workbook

Sheet Начните здесь
D2: Начните здесь
B3: Елизавета Трибунская | F3: tribunska.ru
B5: Прикрепите эту книгу к чату с вашим ИИ-агентом и отправьте промпт ниже. Расскажите, что хотите запустить: агент поможет адаптировать модель под ваш бизнес.
B7: Изменить параметры | F7: Посмотреть результат
B9: Хотите посчитать сами? Меняйте жёлтые ячейки на листе «Допущения», а результат смотрите на листе «Итог».
B11: Промпт для вашего агента
B12: Помоги адаптировать приложенную Excel-модель под мою бизнес-идею. Сначала изучи книгу и задай мне вопросы о продукте: кому и что я продаю, как получаю деньги, как привлекаю покупателей, какие расходы и ограничения есть. Спрашивай небольшими порциями, учитывая мои ответы. Разбери, что в модели подходит моему бизнесу, а что нужно изменить. Согласуй со мной изменения логики. Затем создай отдельную адаптированную книгу: можно менять статьи расходов, каналы, структуру и формулы. Исходный файл сохрани. Используй мои данные. Для неизвестных предложи допущения и явно обозначь их. Рыночные ориентиры указывай со ссылками и датами. Раздели разовые и текущие расходы, выручку и денежные поступления; учти налоги и сроки платежей для моего проекта. Посчитай осторожный, базовый и сильный сценарии. Покажи, сколько денег нужно на запуск, когда бизнес выходит в плюс и возвращает вложения. Если это не происходит за выбранный срок, так и напиши. Выдели поля ввода, сохрани расчёты в формулах и проверь, что изменение цены, объёма продаж и расходов меняет результат. Объясни основные изменения и назови три допущения, которые сильнее всего влияют на расчёт и требуют проверки. Если не можешь отредактировать Excel, дай точный список изменений и формул. Моя бизнес-идея: [расскажите, что хотите запустить].
B14: Скопируйте ячейку B12 целиком и вставьте в чат вместе с файлом.
B16: Когда появятся первые цифры, разберём, на какие уже можно опираться и что стоит проверить до запуска.
B17: Обсудить мой проект с Елизаветой

Sheet Итог
A1: Ритм — модель запуска
A2: Концептуальный кейс: все числа — авторские модельные допущения. Денежный поток до налогов; месяц 0 — подготовка, 1–12 — продажи. Месячная подписка оплачивается вперёд; продление — следующая месячная оплата.
A3: Елизавета Трибунская | F3: tribunska.ru | I3: t.me/tribunska
A4: Выбранный сценарий | B4: =INDEX(Допущения!$C$35:$E$35,1,Допущения!$B$3) -> 2 Базовый
A5: Горизонт | B5: 12 месяцев · до налогов и финансирования
A6: Свои параметры вводите в жёлтые ячейки листа «Допущения». Остальные листы показывают расчёт.
A7: Результат выбранного сценария | D7: Помесячный прогноз выбранного сценария
A8: Уникальные новые оплаты за 12 месяцев | B8: =SUM(Подписка!$C$6:$C$17) -> 1360.6389 | D8: Месяц | E8: Холодные визиты | F8: Новые оплаты | G8: Оплаченные | H8: Выручка, ₽ | I8: Расход рекламы, ₽ | J8: Опер. поток, ₽ | K8: Накопленный поток, ₽ | L8: Макс. дефицит к месяцу, ₽
A9: Оплаченные пользователь-месяцы | B9: =SUM(Подписка!$E$6:$E$17) -> 3926.681 | D9: 1 | E9: =Подписка!$B$6 -> 1625 | F9: =Подписка!$C$6 -> 22.305556 | G9: =Подписка!$E$6 -> 22.305556 | H9: =Подписка!$F$6 -> 66693.611 | I9: =Подписка!$S$6 -> 50000 | J9: =Подписка!$T$6 -> -238270.1 | K9: =Деньги!$C$7 -> -978270.1 | L9: =Деньги!$D$7 -> 978270.1
A10: Выручка, ₽ | B10: =SUM(Подписка!$F$6:$F$17) -> 11740776 | D10: 2 | E10: =Подписка!$B$7 -> 3250 | F10: =Подписка!$C$7 -> 44.611111 | G10: =Подписка!$E$7 -> 61.340278 | H10: =Подписка!$F$7 -> 183407.43 | I10: =Подписка!$S$7 -> 100000 | J10: =Подписка!$T$7 -> -216539.64 | K10: =Деньги!$C$8 -> -1194809.7 | L10: =Деньги!$D$8 -> 1194809.7
A11: Операционный поток за 12 месяцев, ₽ | B11: =SUM(Подписка!$T$6:$T$17) -> 1403248.9 | D11: 3 | E11: =Подписка!$B$8 -> 6500 | F11: =Подписка!$C$8 -> 89.222222 | G11: =Подписка!$E$8 -> 135.22743 | H11: =Подписка!$F$8 -> 404330.02 | I11: =Подписка!$S$8 -> 200000 | J11: =Подписка!$T$8 -> -178019.5 | K11: =Деньги!$C$9 -> -1372829.2 | L11: =Деньги!$D$9 -> 1372829.2
A12: Накопленный поток в M12, ₽ | B12: =Деньги!$C$18 -> 663248.9 | D12: 4 | E12: =Подписка!$B$9 -> 9750 | F12: =Подписка!$C$9 -> 133.83333 | G12: =Подписка!$E$9 -> 235.25391 | H12: =Подписка!$F$9 -> 703409.18 | I12: =Подписка!$S$9 -> 300000 | J12: =Подписка!$T$9 -> -91028.955 | K12: =Деньги!$C$10 -> -1463858.2 | L12: =Деньги!$D$10 -> 1463858.2
A13: Максимально требуемые деньги до финансирования, ₽ | B13: =MAX(Деньги!$D$6:$D$18) -> 1463858.2 | D13: 5 | E13: =Подписка!$B$10 -> 9750 | F13: =Подписка!$C$10 -> 133.83333 | G13: =Подписка!$E$10 -> 310.27376 | H13: =Подписка!$F$10 -> 927718.55 | I13: =Подписка!$S$10 -> 300000 | J13: =Подписка!$T$10 -> 27382.7 | K13: =Деньги!$C$11 -> -1436475.5 | L13: =Деньги!$D$11 -> 1463858.2
A14: ="Резерв "&ROUND(Допущения!$B$31*100,6)&"%, отдельно, ₽" -> Резерв 15%, отдельно, ₽ | B14: =MAX(Деньги!$E$6:$E$18) -> 219578.73 | D14: 6 | E14: =Подписка!$B$11 -> 9750 | F14: =Подписка!$C$11 -> 133.83333 | G14: =Подписка!$E$11 -> 366.53866 | H14: =Подписка!$F$11 -> 1095950.6 | I14: =Подписка!$S$11 -> 300000 | J14: =Подписка!$T$11 -> 139603.94 | K14: =Деньги!$C$12 -> -1296871.5 | L14: =Деньги!$D$12 -> 1463858.2
A15: Первый положительный операционный месяц | B15: =IF(COUNTIF(Подписка!$U$6:$U$17,1)=0,"За 12 месяцев не достигнут","M"&MATCH(1,Подписка!$U$6:$U$17,0)) -> M5 | D15: 7 | E15: =Подписка!$B$12 -> 9750 | F15: =Подписка!$C$12 -> 133.83333 | G15: =Подписка!$E$12 -> 408.73733 | H15: =Подписка!$F$12 -> 1222124.6 | I15: =Подписка!$S$12 -> 300000 | J15: =Подписка!$T$12 -> 222416.75 | K15: =Деньги!$C$13 -> -1074454.8 | L15: =Деньги!$D$13 -> 1463858.2
A16: Окупаемость запуска | B16: =IF(COUNTIF(Деньги!$F$7:$F$18,1)=0,"За 12 месяцев не достигнута","M"&MATCH(1,Деньги!$F$7:$F$18,0)) -> M11 | D16: 8 | E16: =Подписка!$B$13 -> 9750 | F16: =Подписка!$C$13 -> 133.83333 | G16: =Подписка!$E$13 -> 440.38633 | H16: =Подписка!$F$13 -> 1316755.1 | I16: =Подписка!$S$13 -> 300000 | J16: =Подписка!$T$13 -> 279113.85 | K16: =Деньги!$C$14 -> -795340.95 | L16: =Деньги!$D$14 -> 1463858.2
A17: Доля бюджетов каналов | B17: =SUM(Допущения!$B$44:$B$47) -> 1 | D17: 9 | E17: =Подписка!$B$14 -> 9750 | F17: =Подписка!$C$14 -> 133.83333 | G17: =Подписка!$E$14 -> 464.12308 | H17: =Подписка!$F$14 -> 1387728 | I17: =Подписка!$S$14 -> 300000 | J17: =Подписка!$T$14 -> 327049.18 | K17: =Деньги!$C$15 -> -468291.77 | L17: =Деньги!$D$15 -> 1463858.2
A18: Финансирование с резервом, ₽ | B18: =SUM(B13:B14) -> 1683436.9 | D18: 10 | E18: =Подписка!$B$15 -> 9750 | F18: =Подписка!$C$15 -> 133.83333 | G18: =Подписка!$E$15 -> 481.92564 | H18: =Подписка!$F$15 -> 1440957.7 | I18: =Подписка!$S$15 -> 300000 | J18: =Подписка!$T$15 -> 360294.43 | K18: =Деньги!$C$16 -> -107997.34 | L18: =Деньги!$D$16 -> 1463858.2
D19: 11 | E19: =Подписка!$B$16 -> 9750 | F19: =Подписка!$C$16 -> 133.83333 | G19: =Подписка!$E$16 -> 495.27757 | H19: =Подписка!$F$16 -> 1480879.9 | I19: =Подписка!$S$16 -> 300000 | J19: =Подписка!$T$16 -> 387934.61 | K19: =Деньги!$C$17 -> 279937.27 | L19: =Деньги!$D$17 -> 1463858.2
D20: 12 | E20: =Подписка!$B$17 -> 9750 | F20: =Подписка!$C$17 -> 133.83333 | G20: =Подписка!$E$17 -> 505.29151 | H20: =Подписка!$F$17 -> 1510821.6 | I20: =Подписка!$S$17 -> 300000 | J20: =Подписка!$T$17 -> 383311.63 | K20: =Деньги!$C$18 -> 663248.9 | L20: =Деньги!$D$18 -> 1463858.2
A23: Предельная оценка юнит-экономики при полном заполнении
A24: Чистая цена после возвратов и комиссии, ₽ | B24: =Допущения!$B$5*(1-Допущения!$B$6-Допущения!$B$7) -> 2840.5
A25: AI на оплатившего в месяц, ₽ | B25: =Допущения!$B$8*Допущения!$B$9 -> 180
A26: Инфраструктура, ₽ | B26: =Допущения!$B$10 -> 60
A27: Поддержка после оплаты, ₽ | B27: =Допущения!$B$11/60*Допущения!$B$12 -> 125
A28: Ведущий на участника заполненной группы, ₽ | B28: =Допущения!$B$15*Допущения!$B$16*Допущения!$B$17/Допущения!$B$39 -> 541.25
A29: Эксперт на участника заполненного блока, ₽ | B29: =Допущения!$B$19*Допущения!$B$20*Допущения!$B$21/Допущения!$B$18 -> 96
A30: После обслуживания за месяц, ₽ | B30: =B24-B25-B26-B27-B28-B29 -> 1838.25
A31: Предел CAC за выбранный срок, ₽ | B31: =B30*IF(Допущения!$B$36=1,Допущения!$B$30,(1-Допущения!$B$36^Допущения!$B$30)/(1-Допущения!$B$36)) -> 4250.9531
A32: Полный CAC с поддержкой до покупки, ₽ | B32: =IF(SUM(Подписка!$C$6:$C$17)=0,"Нет оплат",(SUM(Подписка!$S$6:$S$17)+SUM(Подписка!$L$6:$L$17))/SUM(Подписка!$C$6:$C$17)) -> 2387.2976
A33: Запас до предела CAC, ₽ | B33: =IF(ISNUMBER(B32),B31-B32,"Нет оплат") -> 1863.6555
A34: =Допущения!A68
A35: Удельные расходы показаны при заполненных группах и экспертных блоках. Помесячный расчёт учитывает оплату целых групп и блоков.
A36: ="Подготовка — "&ROUND(SUM(Допущения!$B$25:$B$27)/1000,2)&" тыс. ₽ в месяце 0. Финансирование = максимальный накопленный дефицит + запас "&ROUND(Допущения!$B$31*100,6)&"%." -> Подготовка — 740 тыс. ₽ в месяце 0. Финансирование = максимальный накопленный дефицит + запас 15%.

Sheet Допущения
A1: Ритм — модель запуска
A2: Меняйте жёлтые ячейки. В B3 выберите сценарий: 1 — осторожный, 2 — базовый, 3 — сильный. Все расчёты обновятся.
A3: Активный сценарий, ID 1/2/3 | B3: 2 | D3: 1 Осторожный | E3: 2 Базовый / 3 Сильный
A4: Общие редактируемые параметры
A5: Цена подписки, ₽/мес | B5: 2990
A6: Возвраты, % выручки | B6: 0.02
A7: Комиссия, % выручки | B7: 0.03
A8: Фото в месяц на оплатившего | B8: 60
A9: Стоимость обработки фото, ₽ | B9: 3
A10: Инфраструктура, ₽/чел./мес | B10: 60
A11: Поддержка после оплаты, мин/чел./мес | B11: 10
A12: Ставка поддержки, ₽/ч | B12: 750
A13: Вопросы до покупки, % холодных визитов | B13: 0.02
A14: Время ответа до покупки, мин | B14: 8
A15: Часы ведущего на группу в неделю | B15: 1.25
A16: Недель в месяце | B16: 4.33
... A31: Резерв от максимального дефицита | B31: 0.15
A32: Жёлтые — меняйте | C32: Зелёные — расчёт сценария | E32: Серые — справка
A33: Белые ячейки с результатами и зелёные значения пересчитываются автоматически.
A34: Параметры трёх сценариев
A35: Параметр | B35: Выбранное значение | C35: 1 Осторожный | D35: 2 Базовый | E35: 3 Сильный
A36: Продление к предыдущим оплатам | B36: =IF(AND(COUNT(INDEX(C36:E36,1,$B$3))=1,INDEX(C36:E36,1,$B$3)>=0,INDEX(C36:E36,1,$B$3)<=1),INDEX(C36:E36,1,$B$3),NA()) -> 0.75 | C36: 0.55 | D36: 0.75 | E36: 0.82
A37: Множитель стоимости визита | B37: =IF(AND(COUNT(INDEX(C37:E37,1,$B$3))=1,INDEX(C37:E37,1,$B$3)>0),INDEX(C37:E37,1,$B$3),NA()) -> 1 | C37: 1.25 | D37: 1 | E37: 0.85
A38: Множитель конверсии в оплату | B38: =IF(AND(COUNT(INDEX(C38:E38,1,$B$3))=1,INDEX(C38:E38,1,$B$3)>=0),INDEX(C38:E38,1,$B$3),NA()) -> 1 | C38: 0.65 | D38: 1 | E38: 1.25
A39: Средняя заполненность группы | B39: =IF(AND(COUNT(INDEX(C39:E39,1,$B$3))=1,INDEX(C39:E39,1,$B$3)>=1,ISNUMBER($B$28),$B$28>=1,$B$28=INT($B$28)),MIN(INDEX(C39:E39,1,$B$3),$B$28),NA()) -> 10 | C39: 8 | D39: 10 | E39: 11
A40: В расчёте заполненность группы ограничена максимумом из B28.
A42: Каналы: доли бюджета, цена визита и конверсии
A43: Канал | B43: Доля бюджета | C43: Базовая цена визита, ₽ | D43: Базовая конверсия | E43: Назначение
A44: Поиск Яндекса | B44: 0.4 | C44: 45 | D44: 0.018 | E44: Запрос об учёте питания по фото и приложении; прямой вход в подписку.
A45: РСЯ | B45: 0.25 | C45: 12 | D45: 0.006 | E45: Холодные тематические аудитории; фото еды и понятная задача.
A46: Блогеры и сообщества | B46: 0.25 | C46: 90 | D46: 0.018 | E46: Нативный рассказ о дневнике и малой группе; Telegram и VK как площадки.
A47: Ретаргетинг | B47: 0.1 | C47: 18 | D47: 0.02 | E47: Возврат заинтересованных посетителей; объём ограничен собственной тёплой аудиторией.
A50: Бюджет привлечения по месяцам, ₽
A51: Месяц | B51: Бюджет
A52: 1 | B52: 50000
A53: 2 | B53: 100000
A54: 3 | B54: 200000
A55: 4 | B55: 300000
A56: 5 | B56: 300000
A57: 6 | B57: 300000
...

Sheet Привлечение
A1: Привлечение — расчёт по месяцу и каналу
A2: Новые оплаты — ожидаемое число покупателей. Расход ретаргетинга ограничен доступной аудиторией.
A3: Елизавета Трибунская · tribunska.ru
A5: Месяц | B5: Канал | C5: Бюджет, ₽ | D5: Цена визита, ₽ | E5: Конверсия | F5: Визиты | G5: Новые оплаты | H5: Холодные визиты | I5: Расход рекламы, ₽ | J5: Вопросы до покупки | K5: Поддержка до покупки, ₽
A6: 1 | B6: Поиск Яндекса | C6: =IF(AND(ISNUMBER(Допущения!$B$52),Допущения!$B$52>=0,AND(COUNT(Допущения!$B$44:$B$47)=4,MIN(Допущения!$B$44:$B$47)>=0,MAX(Допущения!$B$44:$B$47)<=1,ABS(SUM(Допущения!$B$44:$B$47)-1)<0.00000001)),Допущения!$B$52*Допущения!$B$44,NA()) -> 20000 | D6: =IF(AND(ISNUMBER(Допущения!$C$44),Допущения!$C$44>0),Допущения!$C$44*Допущения!$B$37,NA()) -> 45 | E6: =IF(AND(ISNUMBER(Допущения!$D$44),Допущения!$D$44>=0,Допущения!$D$44<=1,Допущения!$D$44*Допущения!$B$38<=1),Допущения!$D$44*Допущения!$B$38,NA()) -> 0.018 | F6: =C6/D6 -> 444.44444 | G6: =F6*E6 -> 8 | H6: =F6 -> 444.44444 | I6: =F6*D6 -> 20000 | J6: =H6*Допущения!$B$13 -> 8.8888889 | K6: =J6*Допущения!$B$14/60*Допущения!$B$12 -> 888.88889
A7: 1 | B7: РСЯ | C7: =IF(AND(ISNUMBER(Допущения!$B$52),Допущения!$B$52>=0,AND(COUNT(Допущения!$B$44:$B$47)=4,MIN(Допущения!$B$44:$B$47)>=0,MAX(Допущения!$B$44:$B$47)<=1,ABS(SUM(Допущения!$B$44:$B$47)-1)<0.00000001)),Допущения!$B$52*Допущения!$B$45,NA()) -> 12500 | D7: =IF(AND(ISNUMBER(Допущения!$C$45),Допущения!$C$45>0),Допущения!$C$45*Допущения!$B$37,NA()) -> 12 | E7: =IF(AND(ISNUMBER(Допущения!$D$45),Допущения!$D$45>=0,Допущения!$D$45<=1,Допущения!$D$45*Допущения!$B$38<=1),Допущения!$D$45*Допущения!$B$38,NA()) -> 0.006 | F7: =C7/D7 -> 1041.6667 | G7: =F7*E7 -> 6.25 | H7: =F7 -> 1041.6667 | I7: =F7*D7 -> 12500 | J7: =H7*Допущения!$B$13 -> 20.833333 | K7: =J7*Допущения!$B$14/60*Допущения!$B$12 -> 2083.3333
A8: 1 | B8: Блогеры и сообщества | C8: =IF(AND(ISNUMBER(Допущения!$B$52),Допущения!$B$52>=0,AND(COUNT(Допущения!$B$44:$B$47)=4,MIN(Допущения!$B$44:$B$47)>=0,MAX(Допущения!$B$44:$B$47)<=1,ABS(SUM(Допущения!$B$44:$B$47)-1)<0.00000001)),Допущения!$B$52*Допущения!$B$46,NA()) -> 12500 | D8: =IF(AND(ISNUMBER(Допущения!$C$46),Допущения!$C$46>0),Допущения!$C$46*Допущения!$B$37,NA()) -> 90 | E8: =IF(AND(ISNUMBER(Допущения!$D$46),Допущения!$D$46>=0,Допущения!$D$46<=1,Допущения!$D$46*Допущения!$B$38<=1),Допущения!$D$46*Допущения!$B$38,NA()) -> 0.018 | F8: =C8/D8 -> 138.88889 | G8: =F8*E8 -> 2.5 | H8: =F8 -> 138.88889 | I8: =F8*D8 -> 12500 | J8: =H8*Допущения!$B$13 -> 2.7777778 | K8: =J8*Допущения!$B$14/60*Допущения!$B$12 -> 277.77778
A9: 1 | B9: Ретаргетинг | C9: =IF(AND(ISNUMBER(Допущения!$B$52),Допущения!$B$52>=0,AND(COUNT(Допущения!$B$44:$B$47)=4,MIN(Допущения!$B$44:$B$47)>=0,MAX(Допущения!$B$44:$B$47)<=1,ABS(SUM(Допущения!$B$44:$B$47)-1)<0.00000001)),Допущения!$B$52*Допущения!$B$47,NA()) -> 5000 | D9: =IF(AND(ISNUMBER(Допущения!$C$47),Допущения!$C$47>0),Допущения!$C$47*Допущения!$B$37,NA()) -> 18 | E9: =IF(AND(ISNUMBER(Допущения!$D$47),Допущения!$D$47>=0,Допущения!$D$47<=1,Допущения!$D$47*Допущения!$B$38<=1),Допущения!$D$47*Допущения!$B$38,NA()) -> 0.02 | F9: =MIN(C9/D9,SUM(F6:F8)*Допущения!$B$29) -> 277.77778 | G9: =F9*E9 -> 5.5555556 | H9: =0 -> 0 | I9: =F9*D9 -> 5000 | J9: =0 -> 0 | K9: =J9*Допущения!$B$14/60*Допущения!$B$12 -> 0
A10: 2 | B10: Поиск Яндекса | C10: =IF(AND(ISNUMBER(Допущения!$B$53),Допущения!$B$53>=0,AND(COUNT(Допущения!$B$44:$B$47)=4,MIN(Допущения!$B$44:$B$47)>=0,MAX(Допущения!$B$44:$B$47)<=1,ABS(SUM(Допущения!$B$44:$B$47)-1)<0.00000001)),Допущения!$B$53*Допущения!$B$44,NA()) -> 40000 | D10: =IF(AND(ISNUMBER(Допущения!$C$44),Допущения!$C$44>0),Допущения!$C$44*Допущения!$B$37,NA()) -> 45 | E10: =IF(AND(ISNUMBER(Допущения!$D$44),Допущения!$D$44>=0,Допущения!$D$44<=1,Допущения!$D$44*Допущения!$B$38<=1),Допущения!$D$44*Допущения!$B$38,NA()) -> 0.018 | F10: =C10/D10 -> 888.88889 | G10: =F10*E10 -> 16 | H10: =F10 -> 888.88889 | I10: =F10*D10 -> 40000 | J10: =H10*Допущения!$B$13 -> 17.777778 | K10: =J10*Допущения!$B$14/60*Допущения!$B$12 -> 1777.7778
A11: 2 | B11: РСЯ | C11: =IF(AND(ISNUMBER(Допущения!$B$53),Допущения!$B$53>=0,AND(COUNT(Допущения!$B$44:$B$47)=4,MIN(Допущения!$B$44:$B$47)>=0,MAX(Допущения!$B$44:$B$47)<=1,ABS(SUM(Допущения!$B$44:$B$47)-1)<0.00000001)),Допущения!$B$53*Допущения!$B$45,NA()) -> 25000 | D11: =IF(AND(ISNUMBER(Допущения!$C$45),Допущения!$C$45>0),Допущения!$C$45*Допущения!$B$37,NA()) -> 12 | E11: =IF(AND(ISNUMBER(Допущения!$D$45),Допущения!$D$45>=0,Допущения!$D$45<=1,Допущения!$D$45*Допущения!$B$38<=1),Допущения!$D$45*Допущения!$B$38,NA()) -> 0.006 | F11: =C11/D11 -> 2083.3333 | G11: =F11*E11 -> 12.5 | H11: =F11 -> 2083.3333 | I11: =F11*D11 -> 25000 | J11: =H11*Допущения!$B$13 -> 41.666667 | K11: =J11*Допущения!$B$14/60*Допущения!$B$12 -> 4166.6667
A12: 2 | B12: Блогеры и сообщества | C12: =IF(AND(ISNUMBER(Допущения!$B$53),Допущения!$B$53>=0,AND(COUNT(Допущения!$B$44:$B$47)=4,MIN(Допущения!$B$44:$B$47)>=0,MAX(Допущения!$B$44:$B$47)<=1,ABS(SUM(Допущения!$B$44:$B$47)-1)<0.00000001)),Допущения!$B$53*Допущения!$B$46,NA()) -> 25000 | D12: =IF(AND(ISNUMBER(Допущения!$C$46),Допущения!$C$46>0),Допущения!$C$46*Допущения!$B$37,NA()) -> 90 | E12: =IF(AND(ISNUMBER(Допущения!$D$46),Допущения!$D$46>=0,Допущения!$D$46<=1,Допущения!$D$46*Допущения!$B$38<=1),Допущения!$D$46*Допущения!$B$38,NA()) -> 0.018 | F12: =C12/D12 -> 277.77778 | G12: =F12*E12 -> 5 | H12: =F12 -> 277.77778 | I12: =F12*D12 -> 25000 | J12: =H12*Допущения!$B$13 -> 5.5555556 | K12: =J12*Допущения!$B$14/60*Допущения!$B$12 -> 555.55556
A13: 2 | B13: Ретаргетинг | C13: =IF(AND(ISNUMBER(Допущения!$B$53),Допущения!$B$53>=0,AND(COUNT(Допущения!$B$44:$B$47)=4,MIN(Допущения!$B$44:$B$47)>=0,MAX(Допущения!$B$44:$B$47)<=1,ABS(SUM(Допущения!$B$44:$B$47)-1)<0.00000001)),Допущения!$B$53*Допущения!$B$47,NA()) -> 10000 | D13: =IF(AND(ISNUMBER(Допущения!$C$47),Допущения!$C$47>0),Допущения!$C$47*Допущения!$B$37,NA()) -> 18 | E13: =IF(AND(ISNUMBER(Допущения!$D$47),Допущения!$D$47>=0,Допущения!$D$47<=1,Допущения!$D$47*Допущения!$B$38<=1),Допущения!$D$47*Допущения!$B$38,NA()) -> 0.02 | F13: =MIN(C13/D13,SUM(F10:F12)*Допущения!$B$29) -> 555.55556 | G13: =F13*E13 -> 11.111111 | H13: =0 -> 0 | I13: =F13*D13 -> 10000 | J13: =0 -> 0 | K13: =J13*Допущения!$B$14/60*Допущения!$B$12 -> 0
A14: 3 | B14: Поиск Яндекса | C14: =IF(AND(ISNUMBER(Допущения!$B$54),Допущения!$B$54>=0,AND(COUNT(Допущения!$B$44:$B$47)=4,MIN(Допущения!$B$44:$B$47)>=0,MAX(Допущения!$B$44:$B$47)<=1,ABS(SUM(Допущения!$B$44:$B$47)-1)<0.00000001)),Допущения!$B$54*Допущения!$B$44,NA()) -> 80000 | D14: =IF(AND(ISNUMBER(Допущения!$C$44),Допущения!$C$44>0),Допущения!$C$44*Допущения!$B$37,NA()) -> 45 | E14: =IF(AND(ISNUMBER(Допущения!$D$44),Допущения!$D$44>=0,Допущения!$D$44<=1,Допущения!$D$44*Допущения!$B$38<=1),Допущения!$D$44*Допущения!$B$38,NA()) -> 0.018 | F14: =C14/D14 -> 1777.7778 | G14: =F14*E14 -> 32 | H14: =F14 -> 1777.7778 | I14: =F14*D14 -> 80000 | J14: =H14*Допущения!$B$13 -> 35.555556 | K14: =J14*Допущения!$B$14/60*Допущения!$B$12 -> 3555.5556
A15: 3 | B15: РСЯ | C15: =IF(AND(ISNUMBER(Допущения!$B$54),Допущения!$B$54>=0,AND(COUNT(Допущения!$B$44:$B$47)=4,MIN(Допущения!$B$44:$B$47)>=0,MAX(Допущения!$B$44:$B$47)<=1,ABS(SUM(Допущения!$B$44:$B$47)-1)<0.00000001)),Допущения!$B$54*Допущения!$B$45,NA()) -> 50000 | D15: =IF(AND(ISNUMBER(Допущения!$C$45),Допущения!$C$45>0),Допущения!$C$45*Допущения!$B$37,NA()) -> 12 | E15: =IF(AND(ISNUMBER(Допущения!$D$45),Допущения!$D$45>=0,Допущения!$D$45<=1,Допущения!$D$45*Допущения!$B$38<=1),Допущения!$D$45*Допущения!$B$38,NA()) -> 0.006 | F15: =C15/D15 -> 4166.6667 | G15: =F15*E15 -> 25 | H15: =F15 -> 4166.6667 | I15: =F15*D15 -> 50000 | J15: =H15*Допущения!$B$13 -> 83.333333 | K15: =J15*Допущения!$B$14/60*Допущения!$B$12 -> 8333.3333
A16: 3 | B16: Блогеры и сообщества | C16: =IF(AND(ISNUMBER(Допущения!$B$54),Допущения!$B$54>=0,AND(COUNT(Допущения!$B$44:$B$47)=4,MIN(Допущения!$B$44:$B$47)>=0,MAX(Допущения!$B$44:$B$47)<=1,ABS(SUM(Допущения!$B$44:$B$47)-1)<0.00000001)),Допущения!$B$54*Допущения!$B$46,NA()) -> 50000 | D16: =IF(AND(ISNUMBER(Допущения!$C$46),Допущения!$C$46>0),Допущения!$C$46*Допущения!$B$37,NA()) -> 90 | E16: =IF(AND(ISNUMBER(Допущения!$D$46),Допущения!$D$46>=0,Допущения!$D$46<=1,Допущения!$D$46*Допущения!$B$38<=1),Допущения!$D$46*Допущения!$B$38,NA()) -> 0.018 | F16: =C16/D16 -> 555.55556 | G16: =F16*E16 -> 10 | H16: =F16 -> 555.55556 | I16: =F16*D16 -> 50000 | J16: =H16*Допущения!$B$13 -> 11.111111 | K16: =J16*Допущения!$B$14/60*Допущения!$B$12 -> 1111.1111
A17: 3 | B17: Ретаргетинг | C17: =IF(AND(ISNUMBER(Допущения!$B$54),Допущения!$B$54>=0,AND(COUNT(Допущения!$B$44:$B$47)=4,MIN(Допущения!$B$44:$B$47)>=0,MAX(Допущения!$B$44:$B$47)<=1,ABS(SUM(Допущения!$B$44:$B$47)-1)<0.00000001)),Допущения!$B$54*Допущения!$B$47,NA()) -> 20000 | D17: =IF(AND(ISNUMBER(Допущения!$C$47),Допущения!$C$47>0),Допущения!$C$47*Допущения!$B$37,NA()) -> 18 | E17: =IF(AND(ISNUMBER(Допущения!$D$47),Допущения!$D$47>=0,Допущения!$D$47<=1,Допущения!$D$47*Допущения!$B$38<=1),Допущения!$D$47*Допущения!$B$38,NA()) -> 0.02 | F17: =MIN(C17/D17,SUM(F14:F16)*Допущения!$B$29) -> 1111.1111 | G17: =F17*E17 -> 22.222222 | H17: =0 -> 0 | I17: =F17*D17 -> 20000 | J17: =0 -> 0 | K17: =J17*Допущения!$B$14/60*Допущения!$B$12 -> 0
A18: 4 | B18: Поиск Яндекса | C18: =IF(AND(ISNUMBER(Допущения!$B$55),Допущения!$B$55>=0,AND(COUNT(Допущения!$B$44:$B$47)=4,MIN(Допущения!$B$44:$B$47)>=0,MAX(Допущения!$B$44:$B$47)<=1,ABS(SUM(Допущения!$B$44:$B$47)-1)<0.00000001)),Допущения!$B$55*Допущения!$B$44,NA()) -> 120000 | D18: =IF(AND(ISNUMBER(Допущения!$C$44),Допущения!$C$44>0),Допущения!$C$44*Допущения!$B$37,NA()) -> 45 | E18: =IF(AND(ISNUMBER(Допущения!$D$44),Допущения!$D$44>=0,Допущения!$D$44<=1,Допущения!$D$44*Допущения!$B$38<=1),Допущения!$D$44*Допущения!$B$38,NA()) -> 0.018 | F18: =C18/D18 -> 2666.6667 | G18: =F18*E18 -> 48 | H18: =F18 -> 2666.6667 | I18: =F18*D18 -> 120000 | J18: =H18*Допущения!$B$13 -> 53.333333 | K18: =J18*Допущения!$B$14/60*Допущения!$B$12 -> 5333.3333
A19: 4 | B19: РСЯ | C19: =IF(AND(ISNUMBER(Допущения!$B$55),Допущения!$B$55>=0,AND(COUNT(Допущения!$B$44:$B$47)=4,MIN(Допущения!$B$44:$B$47)>=0,MAX(Допущения!$B$44:$B$47)<=1,ABS(SUM(Допущения!$B$44:$B$47)-1)<0.00000001)),Допущения!$B$55*Допущения!$B$45,NA()) -> 75000 | D19: =IF(AND(ISNUMBER(Допущения!$C$45),Допущения!$C$45>0),Допущения!$C$45*Допущения!$B$37,NA()) -> 12 | E19: =IF(AND(ISNUMBER(Допущения!$D$45),Допущения!$D$45>=0,Допущения!$D$45<=1,Допущения!$D$45*Допущения!$B$38<=1),Допущения!$D$45*Допущения!$B$38,NA()) -> 0.006 | F19: =C19/D19 -> 6250 | G19: =F19*E19 -> 37.5 | H19: =F19 -> 6250 | I19: =F19*D19 -> 75000 | J19: =H19*Допущения!$B$13 -> 125 | K19: =J19*Допущения!$B$14/60*Допущения!$B$12 -> 12500
A20: 4 | B20: Блогеры и сообщества | C20: =IF(AND(ISNUMBER(Допущения!$B$55),Допущения!$B$55>=0,AND(COUNT(Допущения!$B$44:$B$47)=4,MIN(Допущения!$B$44:$B$47)>=0,MAX(Допущения!$B$44:$B$47)<=1,ABS(SUM(Допущения!$B$44:$B$47)-1)<0.00000001)),Допущения!$B$55*Допущения!$B$46,NA()) -> 75000 | D20: =IF(AND(ISNUMBER(Допущения!$C$46),Допущения!$C$46>0),Допущения!$C$46*Допущения!$B$37,NA()) -> 90 | E20: =IF(AND(ISNUMBER(Допущения!$D$46),Допущения!$D$46>=0,Допущения!$D$46<=1,Допущения!$D$46*Допущения!$B$38<=1),Допущения!$D$46*Допущения!$B$38,NA()) -> 0.018 | F20: =C20/D20 -> 833.33333 | G20: =F20*E20 -> 15 | H20: =F20 -> 833.33333 | I20: =F20*D20 -> 75000 | J20: =H20*Допущения!$B$13 -> 16.666667 | K20: =J20*Допущения!$B$14/60*Допущения!$B$12 -> 1666.6667
A21: 4 | B21: Ретаргетинг | C21: =IF(AND(ISNUMBER(Допущения!$B$55),Допущения!$B$55>=0,AND(COUNT(Допущения!$B$44:$B$47)=4,MIN(Допущения!$B$44:$B$47)>=0,MAX(Допущения!$B$44:$B$47)<=1,ABS(SUM(Допущения!$B$44:$B$47)-1)<0.00000001)),Допущения!$B$55*Допущения!$B$47,NA()) -> 30000 | D21: =IF(AND(ISNUMBER(Допущения!$C$47),Допущения!$C$47>0),Допущения!$C$47*Допущения!$B$37,NA()) -> 18 | E21: =IF(AND(ISNUMBER(Допущения!$D$47),Допущения!$D$47>=0,Допущения!$D$47<=1,Допущения!$D$47*Допущения!$B$38<=1),Допущения!$D$47*Допущения!$B$38,NA()) -> 0.02 | F21: =MIN(C21/D21,SUM(F18:F20)*Допущения!$B$29) -> 1666.6667 | G21: =F21*E21 -> 33.333333 | H21: =0 -> 0 | I21: =F21*D21 -> 30000 | J21: =0 -> 0 | K21: =J21*Допущения!$B$14/60*Допущения!$B$12 -> 0
A22: 5 | B22: Поиск Яндекса | C22: =IF(AND(ISNUMBER(Допущения!$B$56),Допущения!$B$56>=0,AND(COUNT(Допущения!$B$44:$B$47)=4,MIN(Допущения!$B$44:$B$47)>=0,MAX(Допущения!$B$44:$B$47)<=1,ABS(SUM(Допущения!$B$44:$B$47)-1)<0.00000001)),Допущения!$B$56*Допущения!$B$44,NA()) -> 120000 | D22: =IF(AND(ISNUMBER(Допущения!$C$44),Допущения!$C$44>0),Допущения!$C$44*Допущения!$B$37,NA()) -> 45 | E22: =IF(AND(ISNUMBER(Допущения!$D$44),Допущения!$D$44>=0,Допущения!$D$44<=1,Допущения!$D$44*Допущения!$B$38<=1),Допущения!$D$44*Допущения!$B$38,NA()) -> 0.018 | F22: =C22/D22 -> 2666.6667 | G22: =F22*E22 -> 48 | H22: =F22 -> 2666.6667 | I22: =F22*D22 -> 120000 | J22: =H22*Допущения!$B$13 -> 53.333333 | K22: =J22*Допущения!$B$14/60*Допущения!$B$12 -> 5333.3333
A23: 5 | B23: РСЯ | C23: =IF(AND(ISNUMBER(Допущения!$B$56),Допущения!$B$56>=0,AND(COUNT(Допущения!$B$44:$B$47)=4,MIN(Допущения!$B$44:$B$47)>=0,MAX(Допущения!$B$44:$B$47)<=1,ABS(SUM(Допущения!$B$44:$B$47)-1)<0.00000001)),Допущения!$B$56*Допущения!$B$45,NA()) -> 75000 | D23: =IF(AND(ISNUMBER(Допущения!$C$45),Допущения!$C$45>0),Допущения!$C$45*Допущения!$B$37,NA()) -> 12 | E23: =IF(AND(ISNUMBER(Допущения!$D$45),Допущения!$D$45>=0,Допущения!$D$45<=1,Допущения!$D$45*Допущения!$B$38<=1),Допущения!$D$45*Допущения!$B$38,NA()) -> 0.006 | F23: =C23/D23 -> 6250 | G23: =F23*E23 -> 37.5 | H23: =F23 -> 6250 | I23: =F23*D23 -> 75000 | J23: =H23*Допущения!$B$13 -> 125 | K23: =J23*Допущения!$B$14/60*Допущения!$B$12 -> 12500
A24: 5 | B24: Блогеры и сообщества | C24: =IF(AND(ISNUMBER(Допущения!$B$56),Допущения!$B$56>=0,AND(COUNT(Допущения!$B$44:$B$47)=4,MIN(Допущения!$B$44:$B$47)>=0,MAX(Допущения!$B$44:$B$47)<=1,ABS(SUM(Допущения!$B$44:$B$47)-1)<0.00000001)),Допущения!$B$56*Допущения!$B$46,NA()) -> 75000 | D24: =IF(AND(ISNUMBER(Допущения!$C$46),Допущения!$C$46>0),Допущения!$C$46*Допущения!$B$37,NA()) -> 90 | E24: =IF(AND(ISNUMBER(Допущения!$D$46),Допущения!$D$46>=0,Допущения!$D$46<=1,Допущения!$D$46*Допущения!$B$38<=1),Допущения!$D$46*Допущения!$B$38,NA()) -> 0.018 | F24: =C24/D24 -> 833.33333 | G24: =F24*E24 -> 15 | H24: =F24 -> 833.33333 | I24: =F24*D24 -> 75000 | J24: =H24*Допущения!$B$13 -> 16.666667 | K24: =J24*Допущения!$B$14/60*Допущения!$B$12 -> 1666.6667
A25: 5 | B25: Ретаргетинг | C25: =IF(AND(ISNUMBER(Допущения!$B$56),Допущения!$B$56>=0,AND(COUNT(Допущения!$B$44:$B$47)=4,MIN(Допущения!$B$44:$B$47)>=0,MAX(Допущения!$B$44:$B$47)<=1,ABS(SUM(Допущения!$B$44:$B$47)-1)<0.00000001)),Допущения!$B$56*Допущения!$B$47,NA()) -> 30000 | D25: =IF(AND(ISNUMBER(Допущения!$C$47),Допущения!$C$47>0),Допущения!$C$47*Допущения!$B$37,NA()) -> 18 | E25: =IF(AND(ISNUMBER(Допущения!$D$47),Допущения!$D$47>=0,Допущения!$D$47<=1,Допущения!$D$47*Допущения!$B$38<=1),Допущения!$D$47*Допущения!$B$38,NA()) -> 0.02 | F25: =MIN(C25/D25,SUM(F22:F24)*Допущения!$B$29) -> 1666.6667 | G25: =F25*E25 -> 33.333333 | H25: =0 -> 0 | I25: =F25*D25 -> 30000 | J25: =0 -> 0 | K25: =J25*Допущения!$B$14/60*Допущения!$B$12 -> 0
A26: 6 | B26: Поиск Яндекса | C26: =IF(AND(ISNUMBER(Допущения!$B$57),Допущения!$B$57>=0,AND(COUNT(Допущения!$B$44:$B$47)=4,MIN(Допущения!$B$44:$B$47)>=0,MAX(Допущения!$B$44:$B$47)<=1,ABS(SUM(Допущения!$B$44:$B$47)-1)<0.00000001)),Допущения!$B$57*Допущения!$B$44,NA()) -> 120000 | D26: =IF(AND(ISNUMBER(Допущения!$C$44),Допущения!$C$44>0),Допущения!$C$44*Допущения!$B$37,NA()) -> 45 | E26: =IF(AND(ISNUMBER(Допущения!$D$44),Допущения!$D$44>=0,Допущения!$D$44<=1,Допущения!$D$44*Допущения!$B$38<=1),Допущения!$D$44*Допущения!$B$38,NA()) -> 0.018 | F26: =C26/D26 -> 2666.6667 | G26: =F26*E26 -> 48 | H26: =F26 -> 2666.6667 | I26: =F26*D26 -> 120000 | J26: =H26*Допущения!$B$13 -> 53.333333 | K26: =J26*Допущения!$B$14/60*Допущения!$B$12 -> 5333.3333
A27: 6 | B27: РСЯ | C27: =IF(AND(ISNUMBER(Допущения!$B$57),Допущения!$B$57>=0,AND(COUNT(Допущения!$B$44:$B$47)=4,MIN(Допущения!$B$44:$B$47)>=0,MAX(Допущения!$B$44:$B$47)<=1,ABS(SUM(Допущения!$B$44:$B$47)-1)<0.00000001)),Допущения!$B$57*Допущения!$B$45,NA()) -> 75000 | D27: =IF(AND(ISNUMBER(Допущения!$C$45),Допущения!$C$45>0),Допущения!$C$45*Допущения!$B$37,NA()) -> 12 | E27: =IF(AND(ISNUMBER(Допущения!$D$45),Допущения!$D$45>=0,Допущения!$D$45<=1,Допущения!$D$45*Допущения!$B$38<=1),Допущения!$D$45*Допущения!$B$38,NA()) -> 0.006 | F27: =C27/D27 -> 6250 | G27: =F27*E27 -> 37.5 | H27: =F27 -> 6250 | I27: =F27*D27 -> 75000 | J27: =H27*Допущения!$B$13 -> 125 | K27: =J27*Допущения!$B$14/60*Допущения!$B$12 -> 12500
A28: 6 | B28: Блогеры и сообщества | C28: =IF(AND(ISNUMBER(Допущения!$B$57),Допущения!$B$57>=0,AND(COUNT(Допущения!$B$44:$B$47)=4,MIN(Допущения!$B$44:$B$47)>=0,MAX(Допущения!$B$44:$B$47)<=1,ABS(SUM(Допущения!$B$44:$B$47)-1)<0.00000001)),Допущения!$B$57*Допущения!$B$46,NA()) -> 75000 | D28: =IF(AND(ISNUMBER(Допущения!$C$46),Допущения!$C$46>0),Допущения!$C$46*Допущения!$B$37,NA()) -> 90 | E28: =IF(AND(ISNUMBER(Допущения!$D$46),Допущения!$D$46>=0,Допущения!$D$46<=1,Допущения!$D$46*Допущения!$B$38<=1),Допущения!$D$46*Допущения!$B$38,NA()) -> 0.018 | F28: =C28/D28 -> 833.33333 | G28: =F28*E28 -> 15 | H28: =F28 -> 833.33333 | I28: =F28*D28 -> 75000 | J28: =H28*Допущения!$B$13 -> 16.666667 | K28: =J28*Допущения!$B$14/60*Допущения!$B$12 -> 1666.6667
A29: 6 | B29: Ретаргетинг | C29: =IF(AND(ISNUMBER(Допущения!$B$57),Допущения!$B$57>=0,AND(COUNT(Допущения!$B$44:$B$47)=4,MIN(Допущения!$B$44:$B$47)>=0,MAX(Допущения!$B$44:$B$47)<=1,ABS(SUM(Допущения!$B$44:$B$47)-1)<0.00000001)),Допущения!$B$57*Допущения!$B$47,NA()) -> 30000 | D29: =IF(AND(ISNUMBER(Допущения!$C$47),Допущения!$C$47>0),Допущения!$C$47*Допущения!$B$37,NA()) -> 18 | E29: =IF(AND(ISNUMBER(Допущения!$D$47),Допущения!$D$47>=0,Допущения!$D$47<=1,Допущения!$D$47*Допущения!$B$38<=1),Допущения!$D$47*Допущения!$B$38,NA()) -> 0.02 | F29: =MIN(C29/D29,SUM(F26:F28)*Допущения!$B$29) -> 1666.6667 | G29: =F29*E29 -> 33.333333 | H29: =0 -> 0 | I29: =F29*D29 -> 30000 | J29: =0 -> 0 | K29: =J29*Допущения!$B$14/60*Допущения!$B$12 -> 0
A30: 7 | B30: Поиск Яндекса | C30: =IF(AND(ISNUMBER(Допущения!$B$58),Допущения!$B$58>=0,AND(COUNT(Допущения!$B$44:$B$47)=4,MIN(Допущения!$B$44:$B$47)>=0,MAX(Допущения!$B$44:$B$47)<=1,ABS(SUM(Допущения!$B$44:$B$47)-1)<0.00000001)),Допущения!$B$58*Допущения!$B$44,NA()) -> 120000 | D30: =IF(AND(ISNUMBER(Допущения!$C$44),Допущения!$C$44>0),Допущения!$C$44*Допущения!$B$37,NA()) -> 45 | E30: =IF(AND(ISNUMBER(Допущения!$D$44),Допущения!$D$44>=0,Допущения!$D$44<=1,Допущения!$D$44*Допущения!$B$38<=1),Допущения!$D$44*Допущения!$B$38,NA()) -> 0.018 | F30: =C30/D30 -> 2666.6667 | G30: =F30*E30 -> 48 | H30: =F30 -> 2666.6667 | I30: =F30*D30 -> 120000 | J30: =H30*Допущения!$B$13 -> 53.333333 | K30: =J30*Допущения!$B$14/60*Допущения!$B$12 -> 5333.3333
A31: 7 | B31: РСЯ | C31: =IF(AND(ISNUMBER(Допущения!$B$58),Допущения!$B$58>=0,AND(COUNT(Допущения!$B$44:$B$47)=4,MIN(Допущения!$B$44:$B$47)>=0,MAX(Допущения!$B$44:$B$47)<=1,ABS(SUM(Допущения!$B$44:$B$47)-1)<0.00000001)),Допущения!$B$58*Допущения!$B$45,NA()) -> 75000 | D31: =IF(AND(ISNUMBER(Допущения!$C$45),Допущения!$C$45>0),Допущения!$C$45*Допущения!$B$37,NA()) -> 12 | E31: =IF(AND(ISNUMBER(Допущения!$D$45),Допущения!$D$45>=0,Допущения!$D$45<=1,Допущения!$D$45*Допущения!$B$38<=1),Допущения!$D$45*Допущения!$B$38,NA()) -> 0.006 | F31: =C31/D31 -> 6250 | G31: =F31*E31 -> 37.5 | H31: =F31 -> 6250 | I31: =F31*D31 -> 75000 | J31: =H31*Допущения!$B$13 -> 125 | K31: =J31*Допущения!$B$14/60*Допущения!$B$12 -> 12500
A32: 7 | B32: Блогеры и сообщества | C32: =IF(AND(ISNUMBER(Допущения!$B$58),Допущения!$B$58>=0,AND(COUNT(Допущения!$B$44:$B$47)=4,MIN(Допущения!$B$44:$B$47)>=0,MAX(Допущения!$B$44:$B$47)<=1,ABS(SUM(Допущения!$B$44:$B$47)-1)<0.00000001)),Допущения!$B$58*Допущения!$B$46,NA()) -> 75000 | D32: =IF(AND(ISNUMBER(Допущения!$C$46),Допущения!$C$46>0),Допущения!$C$46*Допущения!$B$37,NA()) -> 90 | E32: =IF(AND(ISNUMBER(Допущения!$D$46),Допущения!$D$46>=0,Допущения!$D$46<=1,Допущения!$D$46*Допущения!$B$38<=1),Допущения!$D$46*Допущения!$B$38,NA()) -> 0.018 | F32: =C32/D32 -> 833.33333 | G32: =F32*E32 -> 15 | H32: =F32 -> 833.33333 | I32: =F32*D32 -> 75000 | J32: =H32*Допущения!$B$13 -> 16.666667 | K32: =J32*Допущения!$B$14/60*Допущения!$B$12 -> 1666.6667
A33: 7 | B33: Ретаргетинг | C33: =IF(AND(ISNUMBER(Допущения!$B$58),Допущения!$B$58>=0,AND(COUNT(Допущения!$B$44:$B$47)=4,MIN(Допущения!$B$44:$B$47)>=0,MAX(Допущения!$B$44:$B$47)<=1,ABS(SUM(Допущения!$B$44:$B$47)-1)<0.00000001)),Допущения!$B$58*Допущения!$B$47,NA()) -> 30000 | D33: =IF(AND(ISNUMBER(Допущения!$C$47),Допущения!$C$47>0),Допущения!$C$47*Допущения!$B$37,NA()) -> 18 | E33: =IF(AND(ISNUMBER(Допущения!$D$47),Допущения!$D$47>=0,Допущения!$D$47<=1,Допущения!$D$47*Допущения!$B$38<=1),Допущения!$D$47*Допущения!$B$38,NA()) -> 0.02 | F33: =MIN(C33/D33,SUM(F30:F32)*Допущения!$B$29) -> 1666.6667 | G33: =F33*E33 -> 33.333333 | H33: =0 -> 0 | I33: =F33*D33 -> 30000 | J33: =0 -> 0 | K33: =J33*Допущения!$B$14/60*Допущения!$B$12 -> 0
A34: 8 | B34: Поиск Яндекса | C34: =IF(AND(ISNUMBER(Допущения!$B$59),Допущения!$B$59>=0,AND(COUNT(Допущения!$B$44:$B$47)=4,MIN(Допущения!$B$44:$B$47)>=0,MAX(Допущения!$B$44:$B$47)<=1,ABS(SUM(Допущения!$B$44:$B$47)-1)<0.00000001)),Допущения!$B$59*Допущения!$B$44,NA()) -> 120000 | D34: =IF(AND(ISNUMBER(Допущения!$C$44),Допущения!$C$44>0),Допущения!$C$44*Допущения!$B$37,NA()) -> 45 | E34: =IF(AND(ISNUMBER(Допущения!$D$44),Допущения!$D$44>=0,Допущения!$D$44<=1,Допущения!$D$44*Допущения!$B$38<=1),Допущения!$D$44*Допущения!$B$38,NA()) -> 0.018 | F34: =C34/D34 -> 2666.6667 | G34: =F34*E34 -> 48 | H34: =F34 -> 2666.6667 | I34: =F34*D34 -> 120000 | J34: =H34*Допущения!$B$13 -> 53.333333 | K34: =J34*Допущения!$B$14/60*Допущения!$B$12 -> 5333.3333
A35: 8 | B35: РСЯ | C35: =IF(AND(ISNUMBER(Допущения!$B$59),Допущения!$B$59>=0,AND(COUNT(Допущения!$B$44:$B$47)=4,MIN(Допущения!$B$44:$B$47)>=0,MAX(Допущения!$B$44:$B$47)<=1,ABS(SUM(Допущения!$B$44:$B$47)-1)<0.00000001)),Допущения!$B$59*Допущения!$B$45,NA()) -> 75000 | D35: =IF(AND(ISNUMBER(Допущения!$C$45),Допущения!$C$45>0),Допущения!$C$45*Допущения!$B$37,NA()) -> 12 | E35: =IF(AND(ISNUMBER(Допущения!$D$45),Допущения!$D$45>=0,Допущения!$D$45<=1,Допущения!$D$45*Допущения!$B$38<=1),Допущения!$D$45*Допущения!$B$38,NA()) -> 0.006 | F35: =C35/D35 -> 6250 | G35: =F35*E35 -> 37.5 | H35: =F35 -> 6250 | I35: =F35*D35 -> 75000 | J35: =H35*Допущения!$B$13 -> 125 | K35: =J35*Допущения!$B$14/60*Допущения!$B$12 -> 12500
A36: 8 | B36: Блогеры и сообщества | C36: =IF(AND(ISNUMBER(Допущения!$B$59),Допущения!$B$59>=0,AND(COUNT(Допущения!$B$44:$B$47)=4,MIN(Допущения!$B$44:$B$47)>=0,MAX(Допущения!$B$44:$B$47)<=1,ABS(SUM(Допущения!$B$44:$B$47)-1)<0.00000001)),Допущения!$B$59*Допущения!$B$46,NA()) -> 75000 | D36: =IF(AND(ISNUMBER(Допущения!$C$46),Допущения!$C$46>0),Допущения!$C$46*Допущения!$B$37,NA()) -> 90 | E36: =IF(AND(ISNUMBER(Допущения!$D$46),Допущения!$D$46>=0,Допущения!$D$46<=1,Допущения!$D$46*Допущения!$B$38<=1),Допущения!$D$46*Допущения!$B$38,NA()) -> 0.018 | F36: =C36/D36 -> 833.33333 | G36: =F36*E36 -> 15 | H36: =F36 -> 833.33333 | I36: =F36*D36 -> 75000 | J36: =H36*Допущения!$B$13 -> 16.666667 | K36: =J36*Допущения!$B$14/60*Допущения!$B$12 -> 1666.6667
A37: 8 | B37: Ретаргетинг | C37: =IF(AND(ISNUMBER(Допущения!$B$59),Допущения!$B$59>=0,AND(COUNT(Допущения!$B$44:$B$47)=4,MIN(Допущения!$B$44:$B$47)>=0,MAX(Допущения!$B$44:$B$47)<=1,ABS(SUM(Допущения!$B$44:$B$47)-1)<0.00000001)),Допущения!$B$59*Допущения!$B$47,NA()) -> 30000 | D37: =IF(AND(ISNUMBER(Допущения!$C$47),Допущения!$C$47>0),Допущения!$C$47*Допущения!$B$37,NA()) -> 18 | E37: =IF(AND(ISNUMBER(Допущения!$D$47),Допущения!$D$47>=0,Допущения!$D$47<=1,Допущения!$D$47*Допущения!$B$38<=1),Допущения!$D$47*Допущения!$B$38,NA()) -> 0.02 | F37: =MIN(C37/D37,SUM(F34:F36)*Допущения!$B$29) -> 1666.6667 | G37: =F37*E37 -> 33.333333 | H37: =0 -> 0 | I37: =F37*D37 -> 30000 | J37: =0 -> 0 | K37: =J37*Допущения!$B$14/60*Допущения!$B$12 -> 0
A38: 9 | B38: Поиск Яндекса | C38: =IF(AND(ISNUMBER(Допущения!$B$60),Допущения!$B$60>=0,AND(COUNT(Допущения!$B$44:$B$47)=4,MIN(Допущения!$B$44:$B$47)>=0,MAX(Допущения!$B$44:$B$47)<=1,ABS(SUM(Допущения!$B$44:$B$47)-1)<0.00000001)),Допущения!$B$60*Допущения!$B$44,NA()) -> 120000 | D38: =IF(AND(ISNUMBER(Допущения!$C$44),Допущения!$C$44>0),Допущения!$C$44*Допущения!$B$37,NA()) -> 45 | E38: =IF(AND(ISNUMBER(Допущения!$D$44),Допущения!$D$44>=0,Допущения!$D$44<=1,Допущения!$D$44*Допущения!$B$38<=1),Допущения!$D$44*Допущения!$B$38,NA()) -> 0.018 | F38: =C38/D38 -> 2666.6667 | G38: =F38*E38 -> 48 | H38: =F38 -> 2666.6667 | I38: =F38*D38 -> 120000 | J38: =H38*Допущения!$B$13 -> 53.333333 | K38: =J38*Допущения!$B$14/60*Допущения!$B$12 -> 5333.3333
A39: 9 | B39: РСЯ | C39: =IF(AND(ISNUMBER(Допущения!$B$60),Допущения!$B$60>=0,AND(COUNT(Допущения!$B$44:$B$47)=4,MIN(Допущения!$B$44:$B$47)>=0,MAX(Допущения!$B$44:$B$47)<=1,ABS(SUM(Допущения!$B$44:$B$47)-1)<0.00000001)),Допущения!$B$60*Допущения!$B$45,NA()) -> 75000 | D39: =IF(AND(ISNUMBER(Допущения!$C$45),Допущения!$C$45>0),Допущения!$C$45*Допущения!$B$37,NA()) -> 12 | E39: =IF(AND(ISNUMBER(Допущения!$D$45),Допущения!$D$45>=0,Допущения!$D$45<=1,Допущения!$D$45*Допущения!$B$38<=1),Допущения!$D$45*Допущения!$B$38,NA()) -> 0.006 | F39: =C39/D39 -> 6250 | G39: =F39*E39 -> 37.5 | H39: =F39 -> 6250 | I39: =F39*D39 -> 75000 | J39: =H39*Допущения!$B$13 -> 125 | K39: =J39*Допущения!$B$14/60*Допущения!$B$12 -> 12500
A40: 9 | B40: Блогеры и сообщества | C40: =IF(AND(ISNUMBER(Допущения!$B$60),Допущения!$B$60>=0,AND(COUNT(Допущения!$B$44:$B$47)=4,MIN(Допущения!$B$44:$B$47)>=0,MAX(Допущения!$B$44:$B$47)<=1,ABS(SUM(Допущения!$B$44:$B$47)-1)<0.00000001)),Допущения!$B$60*Допущения!$B$46,NA()) -> 75000 | D40: =IF(AND(ISNUMBER(Допущения!$C$46),Допущения!$C$46>0),Допущения!$C$46*Допущения!$B$37,NA()) -> 90 | E40: =IF(AND(ISNUMBER(Допущения!$D$46),Допущения!$D$46>=0,Допущения!$D$46<=1,Допущения!$D$46*Допущения!$B$38<=1),Допущения!$D$46*Допущения!$B$38,NA()) -> 0.018 | F40: =C40/D40 -> 833.33333 | G40: =F40*E40 -> 15 | H40: =F40 -> 833.33333 | I40: =F40*D40 -> 75000 | J40: =H40*Допущения!$B$13 -> 16.666667 | K40: =J40*Допущения!$B$14/60*Допущения!$B$12 -> 1666.6667
A41: 9 | B41: Ретаргетинг | C41: =IF(AND(ISNUMBER(Допущения!$B$60),Допущения!$B$60>=0,AND(COUNT(Допущения!$B$44:$B$47)=4,MIN(Допущения!$B$44:$B$47)>=0,MAX(Допущения!$B$44:$B$47)<=1,ABS(SUM(Допущения!$B$44:$B$47)-1)<0.00000001)),Допущения!$B$60*Допущения!$B$47,NA()) -> 30000 | D41: =IF(AND(ISNUMBER(Допущения!$C$47),Допущения!$C$47>0),Допущения!$C$47*Допущения!$B$37,NA()) -> 18 | E41: =IF(AND(ISNUMBER(Допущения!$D$47),Допущения!$D$47>=0,Допущения!$D$47<=1,Допущения!$D$47*Допущения!$B$38<=1),Допущения!$D$47*Допущения!$B$38,NA()) -> 0.02 | F41: =MIN(C41/D41,SUM(F38:F40)*Допущения!$B$29) -> 1666.6667 | G41: =F41*E41 -> 33.333333 | H41: =0 -> 0 | I41: =F41*D41 -> 30000 | J41: =0 -> 0 | K41: =J41*Допущения!$B$14/60*Допущения!$B$12 -> 0
...

Sheet Подписка
A1: Подписка и обслуживание по месяцам
A2: Продления считаются от оплативших прошлого месяца; возвраты уменьшают поступления. Оплачиваем целые группы и блоки экспертных встреч.
A3: Елизавета Трибунская · tribunska.ru
A5: Месяц | B5: Холодные визиты | C5: Новые | D5: Продления | E5: Оплаченные | F5: Выручка, ₽ | G5: Возвраты, ₽ | H5: Комиссия, ₽ | I5: AI, ₽ | J5: Инфраструктура, ₽ | K5: Поддержка после, ₽ | L5: Поддержка до, ₽ | M5: Группы | N5: Часы ведущего | O5: Ведущий, ₽ | P5: Блоки эксперта | Q5: Эксперт, ₽ | R5: Постоянные, ₽ | S5: Расход рекламы, ₽ | T5: Операционный поток, ₽ | U5: Плюс, индикатор
A6: 1 | B6: =SUM(Привлечение!$H$6:$H$9) -> 1625 | C6: =SUM(Привлечение!$G$6:$G$9) -> 22.305556 | D6: =0 -> 0 | E6: =C6+D6 -> 22.305556 | F6: =E6*Допущения!$B$5 -> 66693.611 | G6: =F6*Допущения!$B$6 -> 1333.8722 | H6: =F6*Допущения!$B$7 -> 2000.8083 | I6: =E6*Допущения!$B$8*Допущения!$B$9 -> 4015 | J6: =E6*Допущения!$B$10 -> 1338.3333 | K6: =E6*Допущения!$B$11/60*Допущения!$B$12 -> 2788.1944 | L6: =SUM(Привлечение!$K$6:$K$9) -> 3250 | M6: =ROUNDUP(E6/Допущения!$B$39,0) -> 3 | N6: =M6*Допущения!$B$15*Допущения!$B$16 -> 16.2375 | O6: =N6*Допущения!$B$17 -> 16237.5 | P6: =ROUNDUP(E6/Допущения!$B$18,0) -> 1 | Q6: =P6*Допущения!$B$19*Допущения!$B$20*Допущения!$B$21 -> 24000 | R6: =SUM(Допущения!$B$22:$B$24) -> 200000 | S6: =SUM(Привлечение!$I$6:$I$9) -> 50000 | T6: =F6-G6-H6-I6-J6-K6-L6-O6-Q6-R6-S6 -> -238270.1 | U6: =IF(T6>0,1,0) -> 0
A7: 2 | B7: =SUM(Привлечение!$H$10:$H$13) -> 3250 | C7: =SUM(Привлечение!$G$10:$G$13) -> 44.611111 | D7: =E6*Допущения!$B$36 -> 16.729167 | E7: =C7+D7 -> 61.340278 | F7: =E7*Допущения!$B$5 -> 183407.43 | G7: =F7*Допущения!$B$6 -> 3668.1486 | H7: =F7*Допущения!$B$7 -> 5502.2229 | I7: =E7*Допущения!$B$8*Допущения!$B$9 -> 11041.25 | J7: =E7*Допущения!$B$10 -> 3680.4167 | K7: =E7*Допущения!$B$11/60*Допущения!$B$12 -> 7667.5347 | L7: =SUM(Привлечение!$K$10:$K$13) -> 6500 | M7: =ROUNDUP(E7/Допущения!$B$39,0) -> 7 | N7: =M7*Допущения!$B$15*Допущения!$B$16 -> 37.8875 | O7: =N7*Допущения!$B$17 -> 37887.5 | P7: =ROUNDUP(E7/Допущения!$B$18,0) -> 1 | Q7: =P7*Допущения!$B$19*Допущения!$B$20*Допущения!$B$21 -> 24000 | R7: =SUM(Допущения!$B$22:$B$24) -> 200000 | S7: =SUM(Привлечение!$I$10:$I$13) -> 100000 | T7: =F7-G7-H7-I7-J7-K7-L7-O7-Q7-R7-S7 -> -216539.64 | U7: =IF(T7>0,1,0) -> 0
A8: 3 | B8: =SUM(Привлечение!$H$14:$H$17) -> 6500 | C8: =SUM(Привлечение!$G$14:$G$17) -> 89.222222 | D8: =E7*Допущения!$B$36 -> 46.005208 | E8: =C8+D8 -> 135.22743 | F8: =E8*Допущения!$B$5 -> 404330.02 | G8: =F8*Допущения!$B$6 -> 8086.6003 | H8: =F8*Допущения!$B$7 -> 12129.901 | I8: =E8*Допущения!$B$8*Допущения!$B$9 -> 24340.938 | J8: =E8*Допущения!$B$10 -> 8113.6458 | K8: =E8*Допущения!$B$11/60*Допущения!$B$12 -> 16903.429 | L8: =SUM(Привлечение!$K$14:$K$17) -> 13000 | M8: =ROUNDUP(E8/Допущения!$B$39,0) -> 14 | N8: =M8*Допущения!$B$15*Допущения!$B$16 -> 75.775 | O8: =N8*Допущения!$B$17 -> 75775 | P8: =ROUNDUP(E8/Допущения!$B$18,0) -> 1 | Q8: =P8*Допущения!$B$19*Допущения!$B$20*Допущения!$B$21 -> 24000 | R8: =SUM(Допущения!$B$22:$B$24) -> 200000 | S8: =SUM(Привлечение!$I$14:$I$17) -> 200000 | T8: =F8-G8-H8-I8-J8-K8-L8-O8-Q8-R8-S8 -> -178019.5 | U8: =IF(T8>0,1,0) -> 0
A9: 4 | B9: =SUM(Привлечение!$H$18:$H$21) -> 9750 | C9: =SUM(Привлечение!$G$18:$G$21) -> 133.83333 | D9: =E8*Допущения!$B$36 -> 101.42057 | E9: =C9+D9 -> 235.25391 | F9: =E9*Допущения!$B$5 -> 703409.18 | G9: =F9*Допущения!$B$6 -> 14068.184 | H9: =F9*Допущения!$B$7 -> 21102.275 | I9: =E9*Допущения!$B$8*Допущения!$B$9 -> 42345.703 | J9: =E9*Допущения!$B$10 -> 14115.234 | K9: =E9*Допущения!$B$11/60*Допущения!$B$12 -> 29406.738 | L9: =SUM(Привлечение!$K$18:$K$21) -> 19500 | M9: =ROUNDUP(E9/Допущения!$B$39,0) -> 24 | N9: =M9*Допущения!$B$15*Допущения!$B$16 -> 129.9 | O9: =N9*Допущения!$B$17 -> 129900 | P9: =ROUNDUP(E9/Допущения!$B$18,0) -> 1 | Q9: =P9*Допущения!$B$19*Допущения!$B$20*Допущения!$B$21 -> 24000 | R9: =SUM(Допущения!$B$22:$B$24) -> 200000 | S9: =SUM(Привлечение!$I$18:$I$21) -> 300000 | T9: =F9-G9-H9-I9-J9-K9-L9-O9-Q9-R9-S9 -> -91028.955 | U9: =IF(T9>0,1,0) -> 0
A10: 5 | B10: =SUM(Привлечение!$H$22:$H$25) -> 9750 | C10: =SUM(Привлечение!$G$22:$G$25) -> 133.83333 | D10: =E9*Допущения!$B$36 -> 176.44043 | E10: =C10+D10 -> 310.27376 | F10: =E10*Допущения!$B$5 -> 927718.55 | G10: =F10*Допущения!$B$6 -> 18554.371 | H10: =F10*Допущения!$B$7 -> 27831.557 | I10: =E10*Допущения!$B$8*Допущения!$B$9 -> 55849.277 | J10: =E10*Допущения!$B$10 -> 18616.426 | K10: =E10*Допущения!$B$11/60*Допущения!$B$12 -> 38784.22 | L10: =SUM(Привлечение!$K$22:$K$25) -> 19500 | M10: =ROUNDUP(E10/Допущения!$B$39,0) -> 32 | N10: =M10*Допущения!$B$15*Допущения!$B$16 -> 173.2 | O10: =N10*Допущения!$B$17 -> 173200 | P10: =ROUNDUP(E10/Допущения!$B$18,0) -> 2 | Q10: =P10*Допущения!$B$19*Допущения!$B$20*Допущения!$B$21 -> 48000 | R10: =SUM(Допущения!$B$22:$B$24) -> 200000 | S10: =SUM(Привлечение!$I$22:$I$25) -> 300000 | T10: =F10-G10-H10-I10-J10-K10-L10-O10-Q10-R10-S10 -> 27382.7 | U10: =IF(T10>0,1,0) -> 1
A11: 6 | B11: =SUM(Привлечение!$H$26:$H$29) -> 9750 | C11: =SUM(Привлечение!$G$26:$G$29) -> 133.83333 | D11: =E10*Допущения!$B$36 -> 232.70532 | E11: =C11+D11 -> 366.53866 | F11: =E11*Допущения!$B$5 -> 1095950.6 | G11: =F11*Допущения!$B$6 -> 21919.012 | H11: =F11*Допущения!$B$7 -> 32878.517 | I11: =E11*Допущения!$B$8*Допущения!$B$9 -> 65976.958 | J11: =E11*Допущения!$B$10 -> 21992.319 | K11: =E11*Допущения!$B$11/60*Допущения!$B$12 -> 45817.332 | L11: =SUM(Привлечение!$K$26:$K$29) -> 19500 | M11: =ROUNDUP(E11/Допущения!$B$39,0) -> 37 | N11: =M11*Допущения!$B$15*Допущения!$B$16 -> 200.2625 | O11: =N11*Допущения!$B$17 -> 200262.5 | P11: =ROUNDUP(E11/Допущения!$B$18,0) -> 2 | Q11: =P11*Допущения!$B$19*Допущения!$B$20*Допущения!$B$21 -> 48000 | R11: =SUM(Допущения!$B$22:$B$24) -> 200000 | S11: =SUM(Привлечение!$I$26:$I$29) -> 300000 | T11: =F11-G11-H11-I11-J11-K11-L11-O11-Q11-R11-S11 -> 139603.94 | U11: =IF(T11>0,1,0) -> 1
A12: 7 | B12: =SUM(Привлечение!$H$30:$H$33) -> 9750 | C12: =SUM(Привлечение!$G$30:$G$33) -> 133.83333 | D12: =E11*Допущения!$B$36 -> 274.90399 | E12: =C12+D12 -> 408.73733 | F12: =E12*Допущения!$B$5 -> 1222124.6 | G12: =F12*Допущения!$B$6 -> 24442.492 | H12: =F12*Допущения!$B$7 -> 36663.738 | I12: =E12*Допущения!$B$8*Допущения!$B$9 -> 73572.719 | J12: =E12*Допущения!$B$10 -> 24524.24 | K12: =E12*Допущения!$B$11/60*Допущения!$B$12 -> 51092.166 | L12: =SUM(Привлечение!$K$30:$K$33) -> 19500 | M12: =ROUNDUP(E12/Допущения!$B$39,0) -> 41 | N12: =M12*Допущения!$B$15*Допущения!$B$16 -> 221.9125 | O12: =N12*Допущения!$B$17 -> 221912.5 | P12: =ROUNDUP(E12/Допущения!$B$18,0) -> 2 | Q12: =P12*Допущения!$B$19*Допущения!$B$20*Допущения!$B$21 -> 48000 | R12: =SUM(Допущения!$B$22:$B$24) -> 200000 | S12: =SUM(Привлечение!$I$30:$I$33) -> 300000 | T12: =F12-G12-H12-I12-J12-K12-L12-O12-Q12-R12-S12 -> 222416.75 | U12: =IF(T12>0,1,0) -> 1
A13: 8 | B13: =SUM(Привлечение!$H$34:$H$37) -> 9750 | C13: =SUM(Привлечение!$G$34:$G$37) -> 133.83333 | D13: =E12*Допущения!$B$36 -> 306.55299 | E13: =C13+D13 -> 440.38633 | F13: =E13*Допущения!$B$5 -> 1316755.1 | G13: =F13*Допущения!$B$6 -> 26335.102 | H13: =F13*Допущения!$B$7 -> 39502.654 | I13: =E13*Допущения!$B$8*Допущения!$B$9 -> 79269.539 | J13: =E13*Допущения!$B$10 -> 26423.18 | K13: =E13*Допущения!$B$11/60*Допущения!$B$12 -> 55048.291 | L13: =SUM(Привлечение!$K$34:$K$37) -> 19500 | M13: =ROUNDUP(E13/Допущения!$B$39,0) -> 45 | N13: =M13*Допущения!$B$15*Допущения!$B$16 -> 243.5625 | O13: =N13*Допущения!$B$17 -> 243562.5 | P13: =ROUNDUP(E13/Допущения!$B$18,0) -> 2 | Q13: =P13*Допущения!$B$19*Допущения!$B$20*Допущения!$B$21 -> 48000 | R13: =SUM(Допущения!$B$22:$B$24) -> 200000 | S13: =SUM(Привлечение!$I$34:$I$37) -> 300000 | T13: =F13-G13-H13-I13-J13-K13-L13-O13-Q13-R13-S13 -> 279113.85 | U13: =IF(T13>0,1,0) -> 1
A14: 9 | B14: =SUM(Привлечение!$H$38:$H$41) -> 9750 | C14: =SUM(Привлечение!$G$38:$G$41) -> 133.83333 | D14: =E13*Допущения!$B$36 -> 330.28975 | E14: =C14+D14 -> 464.12308 | F14: =E14*Допущения!$B$5 -> 1387728 | G14: =F14*Допущения!$B$6 -> 27754.56 | H14: =F14*Допущения!$B$7 -> 41631.84 | I14: =E14*Допущения!$B$8*Допущения!$B$9 -> 83542.154 | J14: =E14*Допущения!$B$10 -> 27847.385 | K14: =E14*Допущения!$B$11/60*Допущения!$B$12 -> 58015.385 | L14: =SUM(Привлечение!$K$38:$K$41) -> 19500 | M14: =ROUNDUP(E14/Допущения!$B$39,0) -> 47 | N14: =M14*Допущения!$B$15*Допущения!$B$16 -> 254.3875 | O14: =N14*Допущения!$B$17 -> 254387.5 | P14: =ROUNDUP(E14/Допущения!$B$18,0) -> 2 | Q14: =P14*Допущения!$B$19*Допущения!$B$20*Допущения!$B$21 -> 48000 | R14: =SUM(Допущения!$B$22:$B$24) -> 200000 | S14: =SUM(Привлечение!$I$38:$I$41) -> 300000 | T14: =F14-G14-H14-I14-J14-K14-L14-O14-Q14-R14-S14 -> 327049.18 | U14: =IF(T14>0,1,0) -> 1
A15: 10 | B15: =SUM(Привлечение!$H$42:$H$45) -> 9750 | C15: =SUM(Привлечение!$G$42:$G$45) -> 133.83333 | D15: =E14*Допущения!$B$36 -> 348.09231 | E15: =C15+D15 -> 481.92564 | F15: =E15*Допущения!$B$5 -> 1440957.7 | G15: =F15*Допущения!$B$6 -> 28819.153 | H15: =F15*Допущения!$B$7 -> 43228.73 | I15: =E15*Допущения!$B$8*Допущения!$B$9 -> 86746.616 | J15: =E15*Допущения!$B$10 -> 28915.539 | K15: =E15*Допущения!$B$11/60*Допущения!$B$12 -> 60240.705 | L15: =SUM(Привлечение!$K$42:$K$45) -> 19500 | M15: =ROUNDUP(E15/Допущения!$B$39,0) -> 49 | N15: =M15*Допущения!$B$15*Допущения!$B$16 -> 265.2125 | O15: =N15*Допущения!$B$17 -> 265212.5 | P15: =ROUNDUP(E15/Допущения!$B$18,0) -> 2 | Q15: =P15*Допущения!$B$19*Допущения!$B$20*Допущения!$B$21 -> 48000 | R15: =SUM(Допущения!$B$22:$B$24) -> 200000 | S15: =SUM(Привлечение!$I$42:$I$45) -> 300000 | T15: =F15-G15-H15-I15-J15-K15-L15-O15-Q15-R15-S15 -> 360294.43 | U15: =IF(T15>0,1,0) -> 1
A16: 11 | B16: =SUM(Привлечение!$H$46:$H$49) -> 9750 | C16: =SUM(Привлечение!$G$46:$G$49) -> 133.83333 | D16: =E15*Допущения!$B$36 -> 361.44423 | E16: =C16+D16 -> 495.27757 | F16: =E16*Допущения!$B$5 -> 1480879.9 | G16: =F16*Допущения!$B$6 -> 29617.598 | H16: =F16*Допущения!$B$7 -> 44426.398 | I16: =E16*Допущения!$B$8*Допущения!$B$9 -> 89149.962 | J16: =E16*Допущения!$B$10 -> 29716.654 | K16: =E16*Допущения!$B$11/60*Допущения!$B$12 -> 61909.696 | L16: =SUM(Привлечение!$K$46:$K$49) -> 19500 | M16: =ROUNDUP(E16/Допущения!$B$39,0) -> 50 | N16: =M16*Допущения!$B$15*Допущения!$B$16 -> 270.625 | O16: =N16*Допущения!$B$17 -> 270625 | P16: =ROUNDUP(E16/Допущения!$B$18,0) -> 2 | Q16: =P16*Допущения!$B$19*Допущения!$B$20*Допущения!$B$21 -> 48000 | R16: =SUM(Допущения!$B$22:$B$24) -> 200000 | S16: =SUM(Привлечение!$I$46:$I$49) -> 300000 | T16: =F16-G16-H16-I16-J16-K16-L16-O16-Q16-R16-S16 -> 387934.61 | U16: =IF(T16>0,1,0) -> 1
A17: 12 | B17: =SUM(Привлечение!$H$50:$H$53) -> 9750 | C17: =SUM(Привлечение!$G$50:$G$53) -> 133.83333 | D17: =E16*Допущения!$B$36 -> 371.45817 | E17: =C17+D17 -> 505.29151 | F17: =E17*Допущения!$B$5 -> 1510821.6 | G17: =F17*Допущения!$B$6 -> 30216.432 | H17: =F17*Допущения!$B$7 -> 45324.648 | I17: =E17*Допущения!$B$8*Допущения!$B$9 -> 90952.471 | J17: =E17*Допущения!$B$10 -> 30317.49 | K17: =E17*Допущения!$B$11/60*Допущения!$B$12 -> 63161.438 | L17: =SUM(Привлечение!$K$50:$K$53) -> 19500 | M17: =ROUNDUP(E17/Допущения!$B$39,0) -> 51 | N17: =M17*Допущения!$B$15*Допущения!$B$16 -> 276.0375 | O17: =N17*Допущения!$B$17 -> 276037.5 | P17: =ROUNDUP(E17/Допущения!$B$18,0) -> 3 | Q17: =P17*Допущения!$B$19*Допущения!$B$20*Допущения!$B$21 -> 72000 | R17: =SUM(Допущения!$B$22:$B$24) -> 200000 | S17: =SUM(Привлечение!$I$50:$I$53) -> 300000 | T17: =F17-G17-H17-I17-J17-K17-L17-O17-Q17-R17-S17 -> 383311.63 | U17: =IF(T17>0,1,0) -> 1

Sheet Деньги
A1: Деньги — накопленный поток до финансирования
A2: M0 — подготовка; M1–M12 — продажи. Требуемые деньги считаются до финансирования, резерв показан отдельно и не входит в расходы.
A3: Елизавета Трибунская · tribunska.ru
A5: Месяц | B5: Операционный поток / старт, ₽ | C5: Накопленный поток, ₽ | D5: Макс. дефицит к месяцу, ₽ | E5: Резерв, ₽ | F5: Момент возврата вложений
A6: 0 | B6: =-SUM(Допущения!$B$25:$B$27) -> -740000 | C6: =B6 -> -740000 | D6: =MAX(0,-MIN($C$6:C6)) -> 740000 | E6: =D6*Допущения!$B$31 -> 111000 | F6: =0 -> 0
A7: 1 | B7: =Подписка!$T$6 -> -238270.1 | C7: =C6+B7 -> -978270.1 | D7: =MAX(0,-MIN($C$6:C7)) -> 978270.1 | E7: =D7*Допущения!$B$31 -> 146740.51 | F7: =IF(AND(C7>=0,COUNTIF($C$7:C7,">=0")=1),1,0) -> 0
A8: 2 | B8: =Подписка!$T$7 -> -216539.64 | C8: =C7+B8 -> -1194809.7 | D8: =MAX(0,-MIN($C$6:C8)) -> 1194809.7 | E8: =D8*Допущения!$B$31 -> 179221.46 | F8: =IF(AND(C8>=0,COUNTIF($C$7:C8,">=0")=1),1,0) -> 0
A9: 3 | B9: =Подписка!$T$8 -> -178019.5 | C9: =C8+B9 -> -1372829.2 | D9: =MAX(0,-MIN($C$6:C9)) -> 1372829.2 | E9: =D9*Допущения!$B$31 -> 205924.39 | F9: =IF(AND(C9>=0,COUNTIF($C$7:C9,">=0")=1),1,0) -> 0
A10: 4 | B10: =Подписка!$T$9 -> -91028.955 | C10: =C9+B10 -> -1463858.2 | D10: =MAX(0,-MIN($C$6:C10)) -> 1463858.2 | E10: =D10*Допущения!$B$31 -> 219578.73 | F10: =IF(AND(C10>=0,COUNTIF($C$7:C10,">=0")=1),1,0) -> 0
A11: 5 | B11: =Подписка!$T$10 -> 27382.7 | C11: =C10+B11 -> -1436475.5 | D11: =MAX(0,-MIN($C$6:C11)) -> 1463858.2 | E11: =D11*Допущения!$B$31 -> 219578.73 | F11: =IF(AND(C11>=0,COUNTIF($C$7:C11,">=0")=1),1,0) -> 0
A12: 6 | B12: =Подписка!$T$11 -> 139603.94 | C12: =C11+B12 -> -1296871.5 | D12: =MAX(0,-MIN($C$6:C12)) -> 1463858.2 | E12: =D12*Допущения!$B$31 -> 219578.73 | F12: =IF(AND(C12>=0,COUNTIF($C$7:C12,">=0")=1),1,0) -> 0
A13: 7 | B13: =Подписка!$T$12 -> 222416.75 | C13: =C12+B13 -> -1074454.8 | D13: =MAX(0,-MIN($C$6:C13)) -> 1463858.2 | E13: =D13*Допущения!$B$31 -> 219578.73 | F13: =IF(AND(C13>=0,COUNTIF($C$7:C13,">=0")=1),1,0) -> 0
A14: 8 | B14: =Подписка!$T$13 -> 279113.85 | C14: =C13+B14 -> -795340.95 | D14: =MAX(0,-MIN($C$6:C14)) -> 1463858.2 | E14: =D14*Допущения!$B$31 -> 219578.73 | F14: =IF(AND(C14>=0,COUNTIF($C$7:C14,">=0")=1),1,0) -> 0
A15: 9 | B15: =Подписка!$T$14 -> 327049.18 | C15: =C14+B15 -> -468291.77 | D15: =MAX(0,-MIN($C$6:C15)) -> 1463858.2 | E15: =D15*Допущения!$B$31 -> 219578.73 | F15: =IF(AND(C15>=0,COUNTIF($C$7:C15,">=0")=1),1,0) -> 0
A16: 10 | B16: =Подписка!$T$15 -> 360294.43 | C16: =C15+B16 -> -107997.34 | D16: =MAX(0,-MIN($C$6:C16)) -> 1463858.2 | E16: =D16*Допущения!$B$31 -> 219578.73 | F16: =IF(AND(C16>=0,COUNTIF($C$7:C16,">=0")=1),1,0) -> 0
A17: 11 | B17: =Подписка!$T$16 -> 387934.61 | C17: =C16+B17 -> 279937.27 | D17: =MAX(0,-MIN($C$6:C17)) -> 1463858.2 | E17: =D17*Допущения!$B$31 -> 219578.73 | F17: =IF(AND(C17>=0,COUNTIF($C$7:C17,">=0")=1),1,0) -> 1
A18: 12 | B18: =Подписка!$T$17 -> 383311.63 | C18: =C17+B18 -> 663248.9 | D18: =MAX(0,-MIN($C$6:C18)) -> 1463858.2 | E18: =D18*Допущения!$B$31 -> 219578.73 | F18: =IF(AND(C18>=0,COUNTIF($C$7:C18,">=0")=1),1,0) -> 0
